Workbook

Sheet ИТОГО
A1: Продукт | B1: Ед. измерения | C1: Грамм в 1 упаковке | D1: Рублей за упаковку | E1: Срок | F1: ИТОГ ед. измерения | G1: ИТОГ УПАКОВОК | H1: =CONCATENATE("ЦЕНА ВСЕГО: ",SUM(H2:H183)) -> #VALUE! | I1: 45506 | J1: 45507 | K1: 45508 | L1: 45509 | M1: 45510 | N1: 45511 | O1: 45512 | P1: 45513 | Q1: 45514 | R1: 45515
A2: ='список продуктов'!A2 -> Баклажан | B2: ='список продуктов'!B2 -> г | C2: ='список продуктов'!C2 -> 1000 | D2: ='список продуктов'!D2 | E2: ='список продуктов'!E2 -> Краткосрочный | F2: =SUM(I2:R2) -> #N/A | G2: =IFERROR(CEILING(F2/C2,1),"Введите занчения") -> Введите занчения | H2: =IFERROR(G2*D2,"Введите занчения") -> Введите занчения | I2: =SUMIF('02.08'!$B$4:$B$11,A2,'02.08'!$C$4:$C$11)+SUMIF('02.08'!$D$4:$D$11,A2,'02.08'!$E$4:$E$11)+SUMIF('02.08'!$F$4:$F$11,A2,'02.08'!$G$4:$G$11)+SUMIF('02.08'!$H$4:$H$11,A2,'02.08'!$I$4:$I$11)+SUMIF('02.08'!$J$4:$J$11,A2,'02.08'!$K$4:$K$11)+SUMIF('02.08'!$L$4:$L$11,A2,'02.08'!$M$4:$M$11)+SUMIF('02.08'!$N$4:$N$11,A2,'02.08'!$O$4:$O$11) -> 0 | J2: =SUMIF('03.08'!$B$4:$B$11,A2,'03.08'!$C$4:$C$11)+SUMIF('03.08'!$D$4:$D$11,A2,'03.08'!$E$4:$E$11)+SUMIF('03.08'!$F$4:$F$11,A2,'03.08'!$G$4:$G$11)+SUMIF('03.08'!$H$4:$H$11,A2,'03.08'!$I$4:$I$11)+SUMIF('03.08'!$J$4:$J$11,A2,'03.08'!$K$4:$K$11)+SUMIF('03.08'!$L$4:$L$11,A2,'03.08'!$M$4:$M$11)+SUMIF('03.08'!$N$4:$N$11,A2,'03.08'!$O$4:$O$11) -> 0 | K2: =SUMIF('04.08'!$B$4:$B$11,A2,'04.08'!$C$4:$C$11)+SUMIF('04.08'!$D$4:$D$11,A2,'04.08'!$E$4:$E$11)+SUMIF('04.08'!$F$4:$F$11,A2,'04.08'!$G$4:$G$11)+SUMIF('04.08'!$H$4:$H$11,A2,'04.08'!$I$4:$I$11)+SUMIF('04.08'!$J$4:$J$11,A2,'04.08'!$K$4:$K$11)+SUMIF('04.08'!$L$4:$L$11,A2,'04.08'!$M$4:$M$11)+SUMIF('04.08'!$N$4:$N$11,A2,'04.08'!$O$4:$O$11) -> 0 | L2: =SUMIF('05.08'!$B$4:$B$11,A2,'05.08'!$C$4:$C$11)+SUMIF('05.08'!$D$4:$D$11,A2,'05.08'!$E$4:$E$11)+SUMIF('05.08'!$F$4:$F$11,A2,'05.08'!$G$4:$G$11)+SUMIF('05.08'!$H$4:$H$11,A2,'05.08'!$I$4:$I$11)+SUMIF('05.08'!$J$4:$J$11,A2,'05.08'!$K$4:$K$11)+SUMIF('05.08'!$L$4:$L$11,A2,'05.08'!$M$4:$M$11)+SUMIF('05.08'!$N$4:$N$11,A2,'05.08'!$O$4:$O$11) -> 0 | M2: =SUMIF('06.08'!$B$4:$B$11,A2,'06.08'!$C$4:$C$11)+SUMIF('06.08'!$D$4:$D$11,A2,'06.08'!$E$4:$E$11)+SUMIF('06.08'!$F$4:$F$11,A2,'06.08'!$G$4:$G$11)+SUMIF('06.08'!$H$4:$H$11,A2,'06.08'!$I$4:$I$11)+SUMIF('06.08'!$J$4:$J$11,A2,'06.08'!$K$4:$K$11)+SUMIF('06.08'!$L$4:$L$11,A2,'06.08'!$M$4:$M$11)+SUMIF('06.08'!$N$4:$N$11,A2,'06.08'!$O$4:$O$11) -> 0 | N2: =SUMIF('07.08'!$B$4:$B$11,A2,'07.08'!$C$4:$C$11)+SUMIF('07.08'!$D$4:$D$11,A2,'07.08'!$E$4:$E$11)+SUMIF('07.08'!$F$4:$F$11,A2,'07.08'!$G$4:$G$11)+SUMIF('07.08'!$H$4:$H$11,A2,'07.08'!$I$4:$I$11)+SUMIF('07.08'!$J$4:$J$11,A2,'07.08'!$K$4:$K$11)+SUMIF('07.08'!$L$4:$L$11,A2,'07.08'!$M$4:$M$11)+SUMIF('07.08'!$N$4:$N$11,A2,'07.08'!$O$4:$O$11) -> 0 | O2: =SUMIF('08.08'!$B$4:$B$11,A2,'08.08'!$C$4:$C$11)+SUMIF('08.08'!$D$4:$D$11,A2,'08.08'!$E$4:$E$11)+SUMIF('08.08'!$F$4:$F$11,A2,'08.08'!$G$4:$G$11)+SUMIF('08.08'!$H$4:$H$11,A2,'08.08'!$I$4:$I$11)+SUMIF('08.08'!$J$4:$J$11,A2,'08.08'!$K$4:$K$11)+SUMIF('08.08'!$L$4:$L$11,A2,'08.08'!$M$4:$M$11)+SUMIF('08.08'!$N$4:$N$11,A2,'08.08'!$O$4:$O$11) -> 0 | P2: =SUMIF('09.08'!$B$4:$B$11,A2,'09.08'!$C$4:$C$11)+SUMIF('09.08'!$D$4:$D$11,A2,'09.08'!$E$4:$E$11)+SUMIF('09.08'!$F$4:$F$11,A2,'09.08'!$G$4:$G$11)+SUMIF('09.08'!$H$4:$H$11,A2,'09.08'!$I$4:$I$11)+SUMIF('09.08'!$J$4:$J$11,A2,'09.08'!$K$4:$K$11)+SUMIF('09.08'!$L$4:$L$11,A2,'09.08'!$M$4:$M$11)+SUMIF('09.08'!$N$4:$N$11,A2,'09.08'!$O$4:$O$11) -> 0 | Q2: =SUMIF('10.08'!$B$4:$B$11,A2,'10.08'!$C$4:$C$11)+SUMIF('10.08'!$D$4:$D$11,A2,'10.08'!$E$4:$E$11)+SUMIF('10.08'!$F$4:$F$11,A2,'10.08'!$G$4:$G$11)+SUMIF('10.08'!$H$4:$H$11,A2,'10.08'!$I$4:$I$11)+SUMIF('10.08'!$J$4:$J$11,A2,'10.08'!$K$4:$K$11)+SUMIF('10.08'!$L$4:$L$11,A2,'10.08'!$M$4:$M$11)+SUMIF('10.08'!$N$4:$N$11,A2,'10.08'!$O$4:$O$11) -> 0 | R2: =SUMIF('11.08'!$B$4:$B$11,A2,'11.08'!$C$4:$C$11)+SUMIF('11.08'!$D$4:$D$11,A2,'11.08'!$E$4:$E$11)+SUMIF('11.08'!$F$4:$F$11,A2,'11.08'!$G$4:$G$11)+SUMIF('11.08'!$H$4:$H$11,A2,'11.08'!$I$4:$I$11)+SUMIF('11.08'!$J$4:$J$11,A2,'11.08'!$K$4:$K$11)+SUMIF('11.08'!$L$4:$L$11,A2,'11.08'!$M$4:$M$11)+SUMIF('11.08'!$N$4:$N$11,A2,'11.08'!$O$4:$O$11) -> #N/A
A3: ='список продуктов'!A3 -> Бананы | B3: ='список продуктов'!B3 -> г | C3: ='список продуктов'!C3 -> 1000 | D3: ='список продуктов'!D3 | E3: ='список продуктов'!E3 -> Краткосрочный | F3: =SUM(I3:R3) -> #N/A | G3: =IFERROR(CEILING(F3/C3,1),"Введите занчения") -> Введите занчения | H3: =IFERROR(G3*D3,"Введите занчения") -> Введите занчения | I3: =SUMIF('02.08'!$B$4:$B$11,A3,'02.08'!$C$4:$C$11)+SUMIF('02.08'!$D$4:$D$11,A3,'02.08'!$E$4:$E$11)+SUMIF('02.08'!$F$4:$F$11,A3,'02.08'!$G$4:$G$11)+SUMIF('02.08'!$H$4:$H$11,A3,'02.08'!$I$4:$I$11)+SUMIF('02.08'!$J$4:$J$11,A3,'02.08'!$K$4:$K$11)+SUMIF('02.08'!$L$4:$L$11,A3,'02.08'!$M$4:$M$11)+SUMIF('02.08'!$N$4:$N$11,A3,'02.08'!$O$4:$O$11) -> 0 | J3: =SUMIF('03.08'!$B$4:$B$11,A3,'03.08'!$C$4:$C$11)+SUMIF('03.08'!$D$4:$D$11,A3,'03.08'!$E$4:$E$11)+SUMIF('03.08'!$F$4:$F$11,A3,'03.08'!$G$4:$G$11)+SUMIF('03.08'!$H$4:$H$11,A3,'03.08'!$I$4:$I$11)+SUMIF('03.08'!$J$4:$J$11,A3,'03.08'!$K$4:$K$11)+SUMIF('03.08'!$L$4:$L$11,A3,'03.08'!$M$4:$M$11)+SUMIF('03.08'!$N$4:$N$11,A3,'03.08'!$O$4:$O$11) -> 0 | K3: =SUMIF('04.08'!$B$4:$B$11,A3,'04.08'!$C$4:$C$11)+SUMIF('04.08'!$D$4:$D$11,A3,'04.08'!$E$4:$E$11)+SUMIF('04.08'!$F$4:$F$11,A3,'04.08'!$G$4:$G$11)+SUMIF('04.08'!$H$4:$H$11,A3,'04.08'!$I$4:$I$11)+SUMIF('04.08'!$J$4:$J$11,A3,'04.08'!$K$4:$K$11)+SUMIF('04.08'!$L$4:$L$11,A3,'04.08'!$M$4:$M$11)+SUMIF('04.08'!$N$4:$N$11,A3,'04.08'!$O$4:$O$11) -> 0 | L3: =SUMIF('05.08'!$B$4:$B$11,A3,'05.08'!$C$4:$C$11)+SUMIF('05.08'!$D$4:$D$11,A3,'05.08'!$E$4:$E$11)+SUMIF('05.08'!$F$4:$F$11,A3,'05.08'!$G$4:$G$11)+SUMIF('05.08'!$H$4:$H$11,A3,'05.08'!$I$4:$I$11)+SUMIF('05.08'!$J$4:$J$11,A3,'05.08'!$K$4:$K$11)+SUMIF('05.08'!$L$4:$L$11,A3,'05.08'!$M$4:$M$11)+SUMIF('05.08'!$N$4:$N$11,A3,'05.08'!$O$4:$O$11) -> 0 | M3: =SUMIF('06.08'!$B$4:$B$11,A3,'06.08'!$C$4:$C$11)+SUMIF('06.08'!$D$4:$D$11,A3,'06.08'!$E$4:$E$11)+SUMIF('06.08'!$F$4:$F$11,A3,'06.08'!$G$4:$G$11)+SUMIF('06.08'!$H$4:$H$11,A3,'06.08'!$I$4:$I$11)+SUMIF('06.08'!$J$4:$J$11,A3,'06.08'!$K$4:$K$11)+SUMIF('06.08'!$L$4:$L$11,A3,'06.08'!$M$4:$M$11)+SUMIF('06.08'!$N$4:$N$11,A3,'06.08'!$O$4:$O$11) -> 0 | N3: =SUMIF('07.08'!$B$4:$B$11,A3,'07.08'!$C$4:$C$11)+SUMIF('07.08'!$D$4:$D$11,A3,'07.08'!$E$4:$E$11)+SUMIF('07.08'!$F$4:$F$11,A3,'07.08'!$G$4:$G$11)+SUMIF('07.08'!$H$4:$H$11,A3,'07.08'!$I$4:$I$11)+SUMIF('07.08'!$J$4:$J$11,A3,'07.08'!$K$4:$K$11)+SUMIF('07.08'!$L$4:$L$11,A3,'07.08'!$M$4:$M$11)+SUMIF('07.08'!$N$4:$N$11,A3,'07.08'!$O$4:$O$11) -> 0 | O3: =SUMIF('08.08'!$B$4:$B$11,A3,'08.08'!$C$4:$C$11)+SUMIF('08.08'!$D$4:$D$11,A3,'08.08'!$E$4:$E$11)+SUMIF('08.08'!$F$4:$F$11,A3,'08.08'!$G$4:$G$11)+SUMIF('08.08'!$H$4:$H$11,A3,'08.08'!$I$4:$I$11)+SUMIF('08.08'!$J$4:$J$11,A3,'08.08'!$K$4:$K$11)+SUMIF('08.08'!$L$4:$L$11,A3,'08.08'!$M$4:$M$11)+SUMIF('08.08'!$N$4:$N$11,A3,'08.08'!$O$4:$O$11) -> 0 | P3: =SUMIF('09.08'!$B$4:$B$11,A3,'09.08'!$C$4:$C$11)+SUMIF('09.08'!$D$4:$D$11,A3,'09.08'!$E$4:$E$11)+SUMIF('09.08'!$F$4:$F$11,A3,'09.08'!$G$4:$G$11)+SUMIF('09.08'!$H$4:$H$11,A3,'09.08'!$I$4:$I$11)+SUMIF('09.08'!$J$4:$J$11,A3,'09.08'!$K$4:$K$11)+SUMIF('09.08'!$L$4:$L$11,A3,'09.08'!$M$4:$M$11)+SUMIF('09.08'!$N$4:$N$11,A3,'09.08'!$O$4:$O$11) -> 0 | Q3: =SUMIF('10.08'!$B$4:$B$11,A3,'10.08'!$C$4:$C$11)+SUMIF('10.08'!$D$4:$D$11,A3,'10.08'!$E$4:$E$11)+SUMIF('10.08'!$F$4:$F$11,A3,'10.08'!$G$4:$G$11)+SUMIF('10.08'!$H$4:$H$11,A3,'10.08'!$I$4:$I$11)+SUMIF('10.08'!$J$4:$J$11,A3,'10.08'!$K$4:$K$11)+SUMIF('10.08'!$L$4:$L$11,A3,'10.08'!$M$4:$M$11)+SUMIF('10.08'!$N$4:$N$11,A3,'10.08'!$O$4:$O$11) -> 0 | R3: =SUMIF('11.08'!$B$4:$B$11,A3,'11.08'!$C$4:$C$11)+SUMIF('11.08'!$D$4:$D$11,A3,'11.08'!$E$4:$E$11)+SUMIF('11.08'!$F$4:$F$11,A3,'11.08'!$G$4:$G$11)+SUMIF('11.08'!$H$4:$H$11,A3,'11.08'!$I$4:$I$11)+SUMIF('11.08'!$J$4:$J$11,A3,'11.08'!$K$4:$K$11)+SUMIF('11.08'!$L$4:$L$11,A3,'11.08'!$M$4:$M$11)+SUMIF('11.08'!$N$4:$N$11,A3,'11.08'!$O$4:$O$11) -> #N/A | T3: =133261-H47 -> 133261
A4: ='список продуктов'!A5 -> Борщевая заготовка | B4: ='список продуктов'!B5 -> пачка | C4: ='список продуктов'!C5 -> 250 | D4: ='список продуктов'!D5 | E4: ='список продуктов'!E5 -> Долгосрочный | F4: =SUM(I4:R4) -> #N/A | G4: =IFERROR(CEILING(F4/C4,1),"Введите занчения") -> Введите занчения | H4: =IFERROR(G4*D4,"Введите занчения") -> Введите занчения | I4: =SUMIF('02.08'!$B$4:$B$11,A4,'02.08'!$C$4:$C$11)+SUMIF('02.08'!$D$4:$D$11,A4,'02.08'!$E$4:$E$11)+SUMIF('02.08'!$F$4:$F$11,A4,'02.08'!$G$4:$G$11)+SUMIF('02.08'!$H$4:$H$11,A4,'02.08'!$I$4:$I$11)+SUMIF('02.08'!$J$4:$J$11,A4,'02.08'!$K$4:$K$11)+SUMIF('02.08'!$L$4:$L$11,A4,'02.08'!$M$4:$M$11)+SUMIF('02.08'!$N$4:$N$11,A4,'02.08'!$O$4:$O$11) -> 0 | J4: =SUMIF('03.08'!$B$4:$B$11,A4,'03.08'!$C$4:$C$11)+SUMIF('03.08'!$D$4:$D$11,A4,'03.08'!$E$4:$E$11)+SUMIF('03.08'!$F$4:$F$11,A4,'03.08'!$G$4:$G$11)+SUMIF('03.08'!$H$4:$H$11,A4,'03.08'!$I$4:$I$11)+SUMIF('03.08'!$J$4:$J$11,A4,'03.08'!$K$4:$K$11)+SUMIF('03.08'!$L$4:$L$11,A4,'03.08'!$M$4:$M$11)+SUMIF('03.08'!$N$4:$N$11,A4,'03.08'!$O$4:$O$11) -> 0 | K4: =SUMIF('04.08'!$B$4:$B$11,A4,'04.08'!$C$4:$C$11)+SUMIF('04.08'!$D$4:$D$11,A4,'04.08'!$E$4:$E$11)+SUMIF('04.08'!$F$4:$F$11,A4,'04.08'!$G$4:$G$11)+SUMIF('04.08'!$H$4:$H$11,A4,'04.08'!$I$4:$I$11)+SUMIF('04.08'!$J$4:$J$11,A4,'04.08'!$K$4:$K$11)+SUMIF('04.08'!$L$4:$L$11,A4,'04.08'!$M$4:$M$11)+SUMIF('04.08'!$N$4:$N$11,A4,'04.08'!$O$4:$O$11) -> 0 | L4: =SUMIF('05.08'!$B$4:$B$11,A4,'05.08'!$C$4:$C$11)+SUMIF('05.08'!$D$4:$D$11,A4,'05.08'!$E$4:$E$11)+SUMIF('05.08'!$F$4:$F$11,A4,'05.08'!$G$4:$G$11)+SUMIF('05.08'!$H$4:$H$11,A4,'05.08'!$I$4:$I$11)+SUMIF('05.08'!$J$4:$J$11,A4,'05.08'!$K$4:$K$11)+SUMIF('05.08'!$L$4:$L$11,A4,'05.08'!$M$4:$M$11)+SUMIF('05.08'!$N$4:$N$11,A4,'05.08'!$O$4:$O$11) -> 0 | M4: =SUMIF('06.08'!$B$4:$B$11,A4,'06.08'!$C$4:$C$11)+SUMIF('06.08'!$D$4:$D$11,A4,'06.08'!$E$4:$E$11)+SUMIF('06.08'!$F$4:$F$11,A4,'06.08'!$G$4:$G$11)+SUMIF('06.08'!$H$4:$H$11,A4,'06.08'!$I$4:$I$11)+SUMIF('06.08'!$J$4:$J$11,A4,'06.08'!$K$4:$K$11)+SUMIF('06.08'!$L$4:$L$11,A4,'06.08'!$M$4:$M$11)+SUMIF('06.08'!$N$4:$N$11,A4,'06.08'!$O$4:$O$11) -> 0 | N4: =SUMIF('07.08'!$B$4:$B$11,A4,'07.08'!$C$4:$C$11)+SUMIF('07.08'!$D$4:$D$11,A4,'07.08'!$E$4:$E$11)+SUMIF('07.08'!$F$4:$F$11,A4,'07.08'!$G$4:$G$11)+SUMIF('07.08'!$H$4:$H$11,A4,'07.08'!$I$4:$I$11)+SUMIF('07.08'!$J$4:$J$11,A4,'07.08'!$K$4:$K$11)+SUMIF('07.08'!$L$4:$L$11,A4,'07.08'!$M$4:$M$11)+SUMIF('07.08'!$N$4:$N$11,A4,'07.08'!$O$4:$O$11) -> 0 | O4: =SUMIF('08.08'!$B$4:$B$11,A4,'08.08'!$C$4:$C$11)+SUMIF('08.08'!$D$4:$D$11,A4,'08.08'!$E$4:$E$11)+SUMIF('08.08'!$F$4:$F$11,A4,'08.08'!$G$4:$G$11)+SUMIF('08.08'!$H$4:$H$11,A4,'08.08'!$I$4:$I$11)+SUMIF('08.08'!$J$4:$J$11,A4,'08.08'!$K$4:$K$11)+SUMIF('08.08'!$L$4:$L$11,A4,'08.08'!$M$4:$M$11)+SUMIF('08.08'!$N$4:$N$11,A4,'08.08'!$O$4:$O$11) -> 0 | P4: =SUMIF('09.08'!$B$4:$B$11,A4,'09.08'!$C$4:$C$11)+SUMIF('09.08'!$D$4:$D$11,A4,'09.08'!$E$4:$E$11)+SUMIF('09.08'!$F$4:$F$11,A4,'09.08'!$G$4:$G$11)+SUMIF('09.08'!$H$4:$H$11,A4,'09.08'!$I$4:$I$11)+SUMIF('09.08'!$J$4:$J$11,A4,'09.08'!$K$4:$K$11)+SUMIF('09.08'!$L$4:$L$11,A4,'09.08'!$M$4:$M$11)+SUMIF('09.08'!$N$4:$N$11,A4,'09.08'!$O$4:$O$11) -> 0 | Q4: =SUMIF('10.08'!$B$4:$B$11,A4,'10.08'!$C$4:$C$11)+SUMIF('10.08'!$D$4:$D$11,A4,'10.08'!$E$4:$E$11)+SUMIF('10.08'!$F$4:$F$11,A4,'10.08'!$G$4:$G$11)+SUMIF('10.08'!$H$4:$H$11,A4,'10.08'!$I$4:$I$11)+SUMIF('10.08'!$J$4:$J$11,A4,'10.08'!$K$4:$K$11)+SUMIF('10.08'!$L$4:$L$11,A4,'10.08'!$M$4:$M$11)+SUMIF('10.08'!$N$4:$N$11,A4,'10.08'!$O$4:$O$11) -> 0 | R4: =SUMIF('11.08'!$B$4:$B$11,A4,'11.08'!$C$4:$C$11)+SUMIF('11.08'!$D$4:$D$11,A4,'11.08'!$E$4:$E$11)+SUMIF('11.08'!$F$4:$F$11,A4,'11.08'!$G$4:$G$11)+SUMIF('11.08'!$H$4:$H$11,A4,'11.08'!$I$4:$I$11)+SUMIF('11.08'!$J$4:$J$11,A4,'11.08'!$K$4:$K$11)+SUMIF('11.08'!$L$4:$L$11,A4,'11.08'!$M$4:$M$11)+SUMIF('11.08'!$N$4:$N$11,A4,'11.08'!$O$4:$O$11) -> #N/A
A5: ='список продуктов'!A6 -> Булгур | B5: ='список продуктов'!B6 -> пачка | C5: ='список продуктов'!C6 -> 500 | D5: ='список продуктов'!D6 | E5: ='список продуктов'!E6 -> Долгосрочный | F5: =SUM(I5:R5) -> #N/A | G5: =IFERROR(CEILING(F5/C5,1),"Введите занчения") -> Введите занчения | H5: =IFERROR(G5*D5,"Введите занчения") -> Введите занчения | I5: =SUMIF('02.08'!$B$4:$B$11,A5,'02.08'!$C$4:$C$11)+SUMIF('02.08'!$D$4:$D$11,A5,'02.08'!$E$4:$E$11)+SUMIF('02.08'!$F$4:$F$11,A5,'02.08'!$G$4:$G$11)+SUMIF('02.08'!$H$4:$H$11,A5,'02.08'!$I$4:$I$11)+SUMIF('02.08'!$J$4:$J$11,A5,'02.08'!$K$4:$K$11)+SUMIF('02.08'!$L$4:$L$11,A5,'02.08'!$M$4:$M$11)+SUMIF('02.08'!$N$4:$N$11,A5,'02.08'!$O$4:$O$11) -> 0 | J5: =SUMIF('03.08'!$B$4:$B$11,A5,'03.08'!$C$4:$C$11)+SUMIF('03.08'!$D$4:$D$11,A5,'03.08'!$E$4:$E$11)+SUMIF('03.08'!$F$4:$F$11,A5,'03.08'!$G$4:$G$11)+SUMIF('03.08'!$H$4:$H$11,A5,'03.08'!$I$4:$I$11)+SUMIF('03.08'!$J$4:$J$11,A5,'03.08'!$K$4:$K$11)+SUMIF('03.08'!$L$4:$L$11,A5,'03.08'!$M$4:$M$11)+SUMIF('03.08'!$N$4:$N$11,A5,'03.08'!$O$4:$O$11) -> 0 | K5: =SUMIF('04.08'!$B$4:$B$11,A5,'04.08'!$C$4:$C$11)+SUMIF('04.08'!$D$4:$D$11,A5,'04.08'!$E$4:$E$11)+SUMIF('04.08'!$F$4:$F$11,A5,'04.08'!$G$4:$G$11)+SUMIF('04.08'!$H$4:$H$11,A5,'04.08'!$I$4:$I$11)+SUMIF('04.08'!$J$4:$J$11,A5,'04.08'!$K$4:$K$11)+SUMIF('04.08'!$L$4:$L$11,A5,'04.08'!$M$4:$M$11)+SUMIF('04.08'!$N$4:$N$11,A5,'04.08'!$O$4:$O$11) -> 0 | L5: =SUMIF('05.08'!$B$4:$B$11,A5,'05.08'!$C$4:$C$11)+SUMIF('05.08'!$D$4:$D$11,A5,'05.08'!$E$4:$E$11)+SUMIF('05.08'!$F$4:$F$11,A5,'05.08'!$G$4:$G$11)+SUMIF('05.08'!$H$4:$H$11,A5,'05.08'!$I$4:$I$11)+SUMIF('05.08'!$J$4:$J$11,A5,'05.08'!$K$4:$K$11)+SUMIF('05.08'!$L$4:$L$11,A5,'05.08'!$M$4:$M$11)+SUMIF('05.08'!$N$4:$N$11,A5,'05.08'!$O$4:$O$11) -> 0 | M5: =SUMIF('06.08'!$B$4:$B$11,A5,'06.08'!$C$4:$C$11)+SUMIF('06.08'!$D$4:$D$11,A5,'06.08'!$E$4:$E$11)+SUMIF('06.08'!$F$4:$F$11,A5,'06.08'!$G$4:$G$11)+SUMIF('06.08'!$H$4:$H$11,A5,'06.08'!$I$4:$I$11)+SUMIF('06.08'!$J$4:$J$11,A5,'06.08'!$K$4:$K$11)+SUMIF('06.08'!$L$4:$L$11,A5,'06.08'!$M$4:$M$11)+SUMIF('06.08'!$N$4:$N$11,A5,'06.08'!$O$4:$O$11) -> 0 | N5: =SUMIF('07.08'!$B$4:$B$11,A5,'07.08'!$C$4:$C$11)+SUMIF('07.08'!$D$4:$D$11,A5,'07.08'!$E$4:$E$11)+SUMIF('07.08'!$F$4:$F$11,A5,'07.08'!$G$4:$G$11)+SUMIF('07.08'!$H$4:$H$11,A5,'07.08'!$I$4:$I$11)+SUMIF('07.08'!$J$4:$J$11,A5,'07.08'!$K$4:$K$11)+SUMIF('07.08'!$L$4:$L$11,A5,'07.08'!$M$4:$M$11)+SUMIF('07.08'!$N$4:$N$11,A5,'07.08'!$O$4:$O$11) -> 0 | O5: =SUMIF('08.08'!$B$4:$B$11,A5,'08.08'!$C$4:$C$11)+SUMIF('08.08'!$D$4:$D$11,A5,'08.08'!$E$4:$E$11)+SUMIF('08.08'!$F$4:$F$11,A5,'08.08'!$G$4:$G$11)+SUMIF('08.08'!$H$4:$H$11,A5,'08.08'!$I$4:$I$11)+SUMIF('08.08'!$J$4:$J$11,A5,'08.08'!$K$4:$K$11)+SUMIF('08.08'!$L$4:$L$11,A5,'08.08'!$M$4:$M$11)+SUMIF('08.08'!$N$4:$N$11,A5,'08.08'!$O$4:$O$11) -> 0 | P5: =SUMIF('09.08'!$B$4:$B$11,A5,'09.08'!$C$4:$C$11)+SUMIF('09.08'!$D$4:$D$11,A5,'09.08'!$E$4:$E$11)+SUMIF('09.08'!$F$4:$F$11,A5,'09.08'!$G$4:$G$11)+SUMIF('09.08'!$H$4:$H$11,A5,'09.08'!$I$4:$I$11)+SUMIF('09.08'!$J$4:$J$11,A5,'09.08'!$K$4:$K$11)+SUMIF('09.08'!$L$4:$L$11,A5,'09.08'!$M$4:$M$11)+SUMIF('09.08'!$N$4:$N$11,A5,'09.08'!$O$4:$O$11) -> 0 | Q5: =SUMIF('10.08'!$B$4:$B$11,A5,'10.08'!$C$4:$C$11)+SUMIF('10.08'!$D$4:$D$11,A5,'10.08'!$E$4:$E$11)+SUMIF('10.08'!$F$4:$F$11,A5,'10.08'!$G$4:$G$11)+SUMIF('10.08'!$H$4:$H$11,A5,'10.08'!$I$4:$I$11)+SUMIF('10.08'!$J$4:$J$11,A5,'10.08'!$K$4:$K$11)+SUMIF('10.08'!$L$4:$L$11,A5,'10.08'!$M$4:$M$11)+SUMIF('10.08'!$N$4:$N$11,A5,'10.08'!$O$4:$O$11) -> 0 | R5: =SUMIF('11.08'!$B$4:$B$11,A5,'11.08'!$C$4:$C$11)+SUMIF('11.08'!$D$4:$D$11,A5,'11.08'!$E$4:$E$11)+SUMIF('11.08'!$F$4:$F$11,A5,'11.08'!$G$4:$G$11)+SUMIF('11.08'!$H$4:$H$11,A5,'11.08'!$I$4:$I$11)+SUMIF('11.08'!$J$4:$J$11,A5,'11.08'!$K$4:$K$11)+SUMIF('11.08'!$L$4:$L$11,A5,'11.08'!$M$4:$M$11)+SUMIF('11.08'!$N$4:$N$11,A5,'11.08'!$O$4:$O$11) -> #N/A
A6: ='список продуктов'!A7 -> Вермишель | B6: ='список продуктов'!B7 -> пачка | C6: ='список продуктов'!C7 -> 450 | D6: ='список продуктов'!D7 | E6: ='список продуктов'!E7 -> Долгосрочный | F6: =SUM(I6:R6) -> #N/A | G6: =IFERROR(CEILING(F6/C6,1),"Введите занчения") -> Введите занчения | H6: =IFERROR(G6*D6,"Введите занчения") -> Введите занчения | I6: =SUMIF('02.08'!$B$4:$B$11,A6,'02.08'!$C$4:$C$11)+SUMIF('02.08'!$D$4:$D$11,A6,'02.08'!$E$4:$E$11)+SUMIF('02.08'!$F$4:$F$11,A6,'02.08'!$G$4:$G$11)+SUMIF('02.08'!$H$4:$H$11,A6,'02.08'!$I$4:$I$11)+SUMIF('02.08'!$J$4:$J$11,A6,'02.08'!$K$4:$K$11)+SUMIF('02.08'!$L$4:$L$11,A6,'02.08'!$M$4:$M$11)+SUMIF('02.08'!$N$4:$N$11,A6,'02.08'!$O$4:$O$11) -> 0 | J6: =SUMIF('03.08'!$B$4:$B$11,A6,'03.08'!$C$4:$C$11)+SUMIF('03.08'!$D$4:$D$11,A6,'03.08'!$E$4:$E$11)+SUMIF('03.08'!$F$4:$F$11,A6,'03.08'!$G$4:$G$11)+SUMIF('03.08'!$H$4:$H$11,A6,'03.08'!$I$4:$I$11)+SUMIF('03.08'!$J$4:$J$11,A6,'03.08'!$K$4:$K$11)+SUMIF('03.08'!$L$4:$L$11,A6,'03.08'!$M$4:$M$11)+SUMIF('03.08'!$N$4:$N$11,A6,'03.08'!$O$4:$O$11) -> 0 | K6: =SUMIF('04.08'!$B$4:$B$11,A6,'04.08'!$C$4:$C$11)+SUMIF('04.08'!$D$4:$D$11,A6,'04.08'!$E$4:$E$11)+SUMIF('04.08'!$F$4:$F$11,A6,'04.08'!$G$4:$G$11)+SUMIF('04.08'!$H$4:$H$11,A6,'04.08'!$I$4:$I$11)+SUMIF('04.08'!$J$4:$J$11,A6,'04.08'!$K$4:$K$11)+SUMIF('04.08'!$L$4:$L$11,A6,'04.08'!$M$4:$M$11)+SUMIF('04.08'!$N$4:$N$11,A6,'04.08'!$O$4:$O$11) -> 0 | L6: =SUMIF('05.08'!$B$4:$B$11,A6,'05.08'!$C$4:$C$11)+SUMIF('05.08'!$D$4:$D$11,A6,'05.08'!$E$4:$E$11)+SUMIF('05.08'!$F$4:$F$11,A6,'05.08'!$G$4:$G$11)+SUMIF('05.08'!$H$4:$H$11,A6,'05.08'!$I$4:$I$11)+SUMIF('05.08'!$J$4:$J$11,A6,'05.08'!$K$4:$K$11)+SUMIF('05.08'!$L$4:$L$11,A6,'05.08'!$M$4:$M$11)+SUMIF('05.08'!$N$4:$N$11,A6,'05.08'!$O$4:$O$11) -> 0 | M6: =SUMIF('06.08'!$B$4:$B$11,A6,'06.08'!$C$4:$C$11)+SUMIF('06.08'!$D$4:$D$11,A6,'06.08'!$E$4:$E$11)+SUMIF('06.08'!$F$4:$F$11,A6,'06.08'!$G$4:$G$11)+SUMIF('06.08'!$H$4:$H$11,A6,'06.08'!$I$4:$I$11)+SUMIF('06.08'!$J$4:$J$11,A6,'06.08'!$K$4:$K$11)+SUMIF('06.08'!$L$4:$L$11,A6,'06.08'!$M$4:$M$11)+SUMIF('06.08'!$N$4:$N$11,A6,'06.08'!$O$4:$O$11) -> 0 | N6: =SUMIF('07.08'!$B$4:$B$11,A6,'07.08'!$C$4:$C$11)+SUMIF('07.08'!$D$4:$D$11,A6,'07.08'!$E$4:$E$11)+SUMIF('07.08'!$F$4:$F$11,A6,'07.08'!$G$4:$G$11)+SUMIF('07.08'!$H$4:$H$11,A6,'07.08'!$I$4:$I$11)+SUMIF('07.08'!$J$4:$J$11,A6,'07.08'!$K$4:$K$11)+SUMIF('07.08'!$L$4:$L$11,A6,'07.08'!$M$4:$M$11)+SUMIF('07.08'!$N$4:$N$11,A6,'07.08'!$O$4:$O$11) -> 0 | O6: =SUMIF('08.08'!$B$4:$B$11,A6,'08.08'!$C$4:$C$11)+SUMIF('08.08'!$D$4:$D$11,A6,'08.08'!$E$4:$E$11)+SUMIF('08.08'!$F$4:$F$11,A6,'08.08'!$G$4:$G$11)+SUMIF('08.08'!$H$4:$H$11,A6,'08.08'!$I$4:$I$11)+SUMIF('08.08'!$J$4:$J$11,A6,'08.08'!$K$4:$K$11)+SUMIF('08.08'!$L$4:$L$11,A6,'08.08'!$M$4:$M$11)+SUMIF('08.08'!$N$4:$N$11,A6,'08.08'!$O$4:$O$11) -> 0 | P6: =SUMIF('09.08'!$B$4:$B$11,A6,'09.08'!$C$4:$C$11)+SUMIF('09.08'!$D$4:$D$11,A6,'09.08'!$E$4:$E$11)+SUMIF('09.08'!$F$4:$F$11,A6,'09.08'!$G$4:$G$11)+SUMIF('09.08'!$H$4:$H$11,A6,'09.08'!$I$4:$I$11)+SUMIF('09.08'!$J$4:$J$11,A6,'09.08'!$K$4:$K$11)+SUMIF('09.08'!$L$4:$L$11,A6,'09.08'!$M$4:$M$11)+SUMIF('09.08'!$N$4:$N$11,A6,'09.08'!$O$4:$O$11) -> 0 | Q6: =SUMIF('10.08'!$B$4:$B$11,A6,'10.08'!$C$4:$C$11)+SUMIF('10.08'!$D$4:$D$11,A6,'10.08'!$E$4:$E$11)+SUMIF('10.08'!$F$4:$F$11,A6,'10.08'!$G$4:$G$11)+SUMIF('10.08'!$H$4:$H$11,A6,'10.08'!$I$4:$I$11)+SUMIF('10.08'!$J$4:$J$11,A6,'10.08'!$K$4:$K$11)+SUMIF('10.08'!$L$4:$L$11,A6,'10.08'!$M$4:$M$11)+SUMIF('10.08'!$N$4:$N$11,A6,'10.08'!$O$4:$O$11) -> 0 | R6: =SUMIF('11.08'!$B$4:$B$11,A6,'11.08'!$C$4:$C$11)+SUMIF('11.08'!$D$4:$D$11,A6,'11.08'!$E$4:$E$11)+SUMIF('11.08'!$F$4:$F$11,A6,'11.08'!$G$4:$G$11)+SUMIF('11.08'!$H$4:$H$11,A6,'11.08'!$I$4:$I$11)+SUMIF('11.08'!$J$4:$J$11,A6,'11.08'!$K$4:$K$11)+SUMIF('11.08'!$L$4:$L$11,A6,'11.08'!$M$4:$M$11)+SUMIF('11.08'!$N$4:$N$11,A6,'11.08'!$O$4:$O$11) -> #N/A
A7: ='список продуктов'!A8 -> Ветчина | B7: ='список продуктов'!B8 -> г | C7: ='список продуктов'!C8 -> 400 | D7: ='список продуктов'!D8 | E7: ='список продуктов'!E8 -> Краткосрочный | F7: =SUM(I7:R7) -> #N/A | G7: =IFERROR(CEILING(F7/C7,1),"Введите занчения") -> Введите занчения | H7: =IFERROR(G7*D7,"Введите занчения") -> Введите занчения | I7: =SUMIF('02.08'!$B$4:$B$11,A7,'02.08'!$C$4:$C$11)+SUMIF('02.08'!$D$4:$D$11,A7,'02.08'!$E$4:$E$11)+SUMIF('02.08'!$F$4:$F$11,A7,'02.08'!$G$4:$G$11)+SUMIF('02.08'!$H$4:$H$11,A7,'02.08'!$I$4:$I$11)+SUMIF('02.08'!$J$4:$J$11,A7,'02.08'!$K$4:$K$11)+SUMIF('02.08'!$L$4:$L$11,A7,'02.08'!$M$4:$M$11)+SUMIF('02.08'!$N$4:$N$11,A7,'02.08'!$O$4:$O$11) -> 0 | J7: =SUMIF('03.08'!$B$4:$B$11,A7,'03.08'!$C$4:$C$11)+SUMIF('03.08'!$D$4:$D$11,A7,'03.08'!$E$4:$E$11)+SUMIF('03.08'!$F$4:$F$11,A7,'03.08'!$G$4:$G$11)+SUMIF('03.08'!$H$4:$H$11,A7,'03.08'!$I$4:$I$11)+SUMIF('03.08'!$J$4:$J$11,A7,'03.08'!$K$4:$K$11)+SUMIF('03.08'!$L$4:$L$11,A7,'03.08'!$M$4:$M$11)+SUMIF('03.08'!$N$4:$N$11,A7,'03.08'!$O$4:$O$11) -> 0 | K7: =SUMIF('04.08'!$B$4:$B$11,A7,'04.08'!$C$4:$C$11)+SUMIF('04.08'!$D$4:$D$11,A7,'04.08'!$E$4:$E$11)+SUMIF('04.08'!$F$4:$F$11,A7,'04.08'!$G$4:$G$11)+SUMIF('04.08'!$H$4:$H$11,A7,'04.08'!$I$4:$I$11)+SUMIF('04.08'!$J$4:$J$11,A7,'04.08'!$K$4:$K$11)+SUMIF('04.08'!$L$4:$L$11,A7,'04.08'!$M$4:$M$11)+SUMIF('04.08'!$N$4:$N$11,A7,'04.08'!$O$4:$O$11) -> 0 | L7: =SUMIF('05.08'!$B$4:$B$11,A7,'05.08'!$C$4:$C$11)+SUMIF('05.08'!$D$4:$D$11,A7,'05.08'!$E$4:$E$11)+SUMIF('05.08'!$F$4:$F$11,A7,'05.08'!$G$4:$G$11)+SUMIF('05.08'!$H$4:$H$11,A7,'05.08'!$I$4:$I$11)+SUMIF('05.08'!$J$4:$J$11,A7,'05.08'!$K$4:$K$11)+SUMIF('05.08'!$L$4:$L$11,A7,'05.08'!$M$4:$M$11)+SUMIF('05.08'!$N$4:$N$11,A7,'05.08'!$O$4:$O$11) -> 0 | M7: =SUMIF('06.08'!$B$4:$B$11,A7,'06.08'!$C$4:$C$11)+SUMIF('06.08'!$D$4:$D$11,A7,'06.08'!$E$4:$E$11)+SUMIF('06.08'!$F$4:$F$11,A7,'06.08'!$G$4:$G$11)+SUMIF('06.08'!$H$4:$H$11,A7,'06.08'!$I$4:$I$11)+SUMIF('06.08'!$J$4:$J$11,A7,'06.08'!$K$4:$K$11)+SUMIF('06.08'!$L$4:$L$11,A7,'06.08'!$M$4:$M$11)+SUMIF('06.08'!$N$4:$N$11,A7,'06.08'!$O$4:$O$11) -> 0 | N7: =SUMIF('07.08'!$B$4:$B$11,A7,'07.08'!$C$4:$C$11)+SUMIF('07.08'!$D$4:$D$11,A7,'07.08'!$E$4:$E$11)+SUMIF('07.08'!$F$4:$F$11,A7,'07.08'!$G$4:$G$11)+SUMIF('07.08'!$H$4:$H$11,A7,'07.08'!$I$4:$I$11)+SUMIF('07.08'!$J$4:$J$11,A7,'07.08'!$K$4:$K$11)+SUMIF('07.08'!$L$4:$L$11,A7,'07.08'!$M$4:$M$11)+SUMIF('07.08'!$N$4:$N$11,A7,'07.08'!$O$4:$O$11) -> 0 | O7: =SUMIF('08.08'!$B$4:$B$11,A7,'08.08'!$C$4:$C$11)+SUMIF('08.08'!$D$4:$D$11,A7,'08.08'!$E$4:$E$11)+SUMIF('08.08'!$F$4:$F$11,A7,'08.08'!$G$4:$G$11)+SUMIF('08.08'!$H$4:$H$11,A7,'08.08'!$I$4:$I$11)+SUMIF('08.08'!$J$4:$J$11,A7,'08.08'!$K$4:$K$11)+SUMIF('08.08'!$L$4:$L$11,A7,'08.08'!$M$4:$M$11)+SUMIF('08.08'!$N$4:$N$11,A7,'08.08'!$O$4:$O$11) -> 0 | P7: =SUMIF('09.08'!$B$4:$B$11,A7,'09.08'!$C$4:$C$11)+SUMIF('09.08'!$D$4:$D$11,A7,'09.08'!$E$4:$E$11)+SUMIF('09.08'!$F$4:$F$11,A7,'09.08'!$G$4:$G$11)+SUMIF('09.08'!$H$4:$H$11,A7,'09.08'!$I$4:$I$11)+SUMIF('09.08'!$J$4:$J$11,A7,'09.08'!$K$4:$K$11)+SUMIF('09.08'!$L$4:$L$11,A7,'09.08'!$M$4:$M$11)+SUMIF('09.08'!$N$4:$N$11,A7,'09.08'!$O$4:$O$11) -> 0 | Q7: =SUMIF('10.08'!$B$4:$B$11,A7,'10.08'!$C$4:$C$11)+SUMIF('10.08'!$D$4:$D$11,A7,'10.08'!$E$4:$E$11)+SUMIF('10.08'!$F$4:$F$11,A7,'10.08'!$G$4:$G$11)+SUMIF('10.08'!$H$4:$H$11,A7,'10.08'!$I$4:$I$11)+SUMIF('10.08'!$J$4:$J$11,A7,'10.08'!$K$4:$K$11)+SUMIF('10.08'!$L$4:$L$11,A7,'10.08'!$M$4:$M$11)+SUMIF('10.08'!$N$4:$N$11,A7,'10.08'!$O$4:$O$11) -> 0 | R7: =SUMIF('11.08'!$B$4:$B$11,A7,'11.08'!$C$4:$C$11)+SUMIF('11.08'!$D$4:$D$11,A7,'11.08'!$E$4:$E$11)+SUMIF('11.08'!$F$4:$F$11,A7,'11.08'!$G$4:$G$11)+SUMIF('11.08'!$H$4:$H$11,A7,'11.08'!$I$4:$I$11)+SUMIF('11.08'!$J$4:$J$11,A7,'11.08'!$K$4:$K$11)+SUMIF('11.08'!$L$4:$L$11,A7,'11.08'!$M$4:$M$11)+SUMIF('11.08'!$N$4:$N$11,A7,'11.08'!$O$4:$O$11) -> #N/A
A8: ='список продуктов'!A10 -> Гречневая крупа | B8: ='список продуктов'!B10 -> пачка | C8: ='список продуктов'!C10 | D8: ='список продуктов'!D10 | E8: ='список продуктов'!E10 -> Долгосрочный | F8: =SUM(I8:R8) -> #N/A | G8: =IFERROR(CEILING(F8/C8,1),"Введите занчения") -> Введите занчения | H8: =IFERROR(G8*D8,"Введите занчения") -> Введите занчения | I8: =SUMIF('02.08'!$B$4:$B$11,A8,'02.08'!$C$4:$C$11)+SUMIF('02.08'!$D$4:$D$11,A8,'02.08'!$E$4:$E$11)+SUMIF('02.08'!$F$4:$F$11,A8,'02.08'!$G$4:$G$11)+SUMIF('02.08'!$H$4:$H$11,A8,'02.08'!$I$4:$I$11)+SUMIF('02.08'!$J$4:$J$11,A8,'02.08'!$K$4:$K$11)+SUMIF('02.08'!$L$4:$L$11,A8,'02.08'!$M$4:$M$11)+SUMIF('02.08'!$N$4:$N$11,A8,'02.08'!$O$4:$O$11) -> 0 | J8: =SUMIF('03.08'!$B$4:$B$11,A8,'03.08'!$C$4:$C$11)+SUMIF('03.08'!$D$4:$D$11,A8,'03.08'!$E$4:$E$11)+SUMIF('03.08'!$F$4:$F$11,A8,'03.08'!$G$4:$G$11)+SUMIF('03.08'!$H$4:$H$11,A8,'03.08'!$I$4:$I$11)+SUMIF('03.08'!$J$4:$J$11,A8,'03.08'!$K$4:$K$11)+SUMIF('03.08'!$L$4:$L$11,A8,'03.08'!$M$4:$M$11)+SUMIF('03.08'!$N$4:$N$11,A8,'03.08'!$O$4:$O$11) -> 0 | K8: =SUMIF('04.08'!$B$4:$B$11,A8,'04.08'!$C$4:$C$11)+SUMIF('04.08'!$D$4:$D$11,A8,'04.08'!$E$4:$E$11)+SUMIF('04.08'!$F$4:$F$11,A8,'04.08'!$G$4:$G$11)+SUMIF('04.08'!$H$4:$H$11,A8,'04.08'!$I$4:$I$11)+SUMIF('04.08'!$J$4:$J$11,A8,'04.08'!$K$4:$K$11)+SUMIF('04.08'!$L$4:$L$11,A8,'04.08'!$M$4:$M$11)+SUMIF('04.08'!$N$4:$N$11,A8,'04.08'!$O$4:$O$11) -> 0 | L8: =SUMIF('05.08'!$B$4:$B$11,A8,'05.08'!$C$4:$C$11)+SUMIF('05.08'!$D$4:$D$11,A8,'05.08'!$E$4:$E$11)+SUMIF('05.08'!$F$4:$F$11,A8,'05.08'!$G$4:$G$11)+SUMIF('05.08'!$H$4:$H$11,A8,'05.08'!$I$4:$I$11)+SUMIF('05.08'!$J$4:$J$11,A8,'05.08'!$K$4:$K$11)+SUMIF('05.08'!$L$4:$L$11,A8,'05.08'!$M$4:$M$11)+SUMIF('05.08'!$N$4:$N$11,A8,'05.08'!$O$4:$O$11) -> 0 | M8: =SUMIF('06.08'!$B$4:$B$11,A8,'06.08'!$C$4:$C$11)+SUMIF('06.08'!$D$4:$D$11,A8,'06.08'!$E$4:$E$11)+SUMIF('06.08'!$F$4:$F$11,A8,'06.08'!$G$4:$G$11)+SUMIF('06.08'!$H$4:$H$11,A8,'06.08'!$I$4:$I$11)+SUMIF('06.08'!$J$4:$J$11,A8,'06.08'!$K$4:$K$11)+SUMIF('06.08'!$L$4:$L$11,A8,'06.08'!$M$4:$M$11)+SUMIF('06.08'!$N$4:$N$11,A8,'06.08'!$O$4:$O$11) -> 0 | N8: =SUMIF('07.08'!$B$4:$B$11,A8,'07.08'!$C$4:$C$11)+SUMIF('07.08'!$D$4:$D$11,A8,'07.08'!$E$4:$E$11)+SUMIF('07.08'!$F$4:$F$11,A8,'07.08'!$G$4:$G$11)+SUMIF('07.08'!$H$4:$H$11,A8,'07.08'!$I$4:$I$11)+SUMIF('07.08'!$J$4:$J$11,A8,'07.08'!$K$4:$K$11)+SUMIF('07.08'!$L$4:$L$11,A8,'07.08'!$M$4:$M$11)+SUMIF('07.08'!$N$4:$N$11,A8,'07.08'!$O$4:$O$11) -> 0 | O8: =SUMIF('08.08'!$B$4:$B$11,A8,'08.08'!$C$4:$C$11)+SUMIF('08.08'!$D$4:$D$11,A8,'08.08'!$E$4:$E$11)+SUMIF('08.08'!$F$4:$F$11,A8,'08.08'!$G$4:$G$11)+SUMIF('08.08'!$H$4:$H$11,A8,'08.08'!$I$4:$I$11)+SUMIF('08.08'!$J$4:$J$11,A8,'08.08'!$K$4:$K$11)+SUMIF('08.08'!$L$4:$L$11,A8,'08.08'!$M$4:$M$11)+SUMIF('08.08'!$N$4:$N$11,A8,'08.08'!$O$4:$O$11) -> 0 | P8: =SUMIF('09.08'!$B$4:$B$11,A8,'09.08'!$C$4:$C$11)+SUMIF('09.08'!$D$4:$D$11,A8,'09.08'!$E$4:$E$11)+SUMIF('09.08'!$F$4:$F$11,A8,'09.08'!$G$4:$G$11)+SUMIF('09.08'!$H$4:$H$11,A8,'09.08'!$I$4:$I$11)+SUMIF('09.08'!$J$4:$J$11,A8,'09.08'!$K$4:$K$11)+SUMIF('09.08'!$L$4:$L$11,A8,'09.08'!$M$4:$M$11)+SUMIF('09.08'!$N$4:$N$11,A8,'09.08'!$O$4:$O$11) -> 0 | Q8: =SUMIF('10.08'!$B$4:$B$11,A8,'10.08'!$C$4:$C$11)+SUMIF('10.08'!$D$4:$D$11,A8,'10.08'!$E$4:$E$11)+SUMIF('10.08'!$F$4:$F$11,A8,'10.08'!$G$4:$G$11)+SUMIF('10.08'!$H$4:$H$11,A8,'10.08'!$I$4:$I$11)+SUMIF('10.08'!$J$4:$J$11,A8,'10.08'!$K$4:$K$11)+SUMIF('10.08'!$L$4:$L$11,A8,'10.08'!$M$4:$M$11)+SUMIF('10.08'!$N$4:$N$11,A8,'10.08'!$O$4:$O$11) -> 0 | R8: =SUMIF('11.08'!$B$4:$B$11,A8,'11.08'!$C$4:$C$11)+SUMIF('11.08'!$D$4:$D$11,A8,'11.08'!$E$4:$E$11)+SUMIF('11.08'!$F$4:$F$11,A8,'11.08'!$G$4:$G$11)+SUMIF('11.08'!$H$4:$H$11,A8,'11.08'!$I$4:$I$11)+SUMIF('11.08'!$J$4:$J$11,A8,'11.08'!$K$4:$K$11)+SUMIF('11.08'!$L$4:$L$11,A8,'11.08'!$M$4:$M$11)+SUMIF('11.08'!$N$4:$N$11,A8,'11.08'!$O$4:$O$11) -> #N/A
A9: ='список продуктов'!A11 -> Грибная заправка | B9: ='список продуктов'!B11 -> пачка | C9: ='список продуктов'!C11 | D9: ='список продуктов'!D11 | E9: ='список продуктов'!E11 -> Долгосрочный | F9: =SUM(I9:R9) -> #N/A | G9: =IFERROR(CEILING(F9/C9,1),"Введите занчения") -> Введите занчения | H9: =IFERROR(G9*D9,"Введите занчения") -> Введите занчения | I9: =SUMIF('02.08'!$B$4:$B$11,A9,'02.08'!$C$4:$C$11)+SUMIF('02.08'!$D$4:$D$11,A9,'02.08'!$E$4:$E$11)+SUMIF('02.08'!$F$4:$F$11,A9,'02.08'!$G$4:$G$11)+SUMIF('02.08'!$H$4:$H$11,A9,'02.08'!$I$4:$I$11)+SUMIF('02.08'!$J$4:$J$11,A9,'02.08'!$K$4:$K$11)+SUMIF('02.08'!$L$4:$L$11,A9,'02.08'!$M$4:$M$11)+SUMIF('02.08'!$N$4:$N$11,A9,'02.08'!$O$4:$O$11) -> 0 | J9: =SUMIF('03.08'!$B$4:$B$11,A9,'03.08'!$C$4:$C$11)+SUMIF('03.08'!$D$4:$D$11,A9,'03.08'!$E$4:$E$11)+SUMIF('03.08'!$F$4:$F$11,A9,'03.08'!$G$4:$G$11)+SUMIF('03.08'!$H$4:$H$11,A9,'03.08'!$I$4:$I$11)+SUMIF('03.08'!$J$4:$J$11,A9,'03.08'!$K$4:$K$11)+SUMIF('03.08'!$L$4:$L$11,A9,'03.08'!$M$4:$M$11)+SUMIF('03.08'!$N$4:$N$11,A9,'03.08'!$O$4:$O$11) -> 0 | K9: =SUMIF('04.08'!$B$4:$B$11,A9,'04.08'!$C$4:$C$11)+SUMIF('04.08'!$D$4:$D$11,A9,'04.08'!$E$4:$E$11)+SUMIF('04.08'!$F$4:$F$11,A9,'04.08'!$G$4:$G$11)+SUMIF('04.08'!$H$4:$H$11,A9,'04.08'!$I$4:$I$11)+SUMIF('04.08'!$J$4:$J$11,A9,'04.08'!$K$4:$K$11)+SUMIF('04.08'!$L$4:$L$11,A9,'04.08'!$M$4:$M$11)+SUMIF('04.08'!$N$4:$N$11,A9,'04.08'!$O$4:$O$11) -> 0 | L9: =SUMIF('05.08'!$B$4:$B$11,A9,'05.08'!$C$4:$C$11)+SUMIF('05.08'!$D$4:$D$11,A9,'05.08'!$E$4:$E$11)+SUMIF('05.08'!$F$4:$F$11,A9,'05.08'!$G$4:$G$11)+SUMIF('05.08'!$H$4:$H$11,A9,'05.08'!$I$4:$I$11)+SUMIF('05.08'!$J$4:$J$11,A9,'05.08'!$K$4:$K$11)+SUMIF('05.08'!$L$4:$L$11,A9,'05.08'!$M$4:$M$11)+SUMIF('05.08'!$N$4:$N$11,A9,'05.08'!$O$4:$O$11) -> 0 | M9: =SUMIF('06.08'!$B$4:$B$11,A9,'06.08'!$C$4:$C$11)+SUMIF('06.08'!$D$4:$D$11,A9,'06.08'!$E$4:$E$11)+SUMIF('06.08'!$F$4:$F$11,A9,'06.08'!$G$4:$G$11)+SUMIF('06.08'!$H$4:$H$11,A9,'06.08'!$I$4:$I$11)+SUMIF('06.08'!$J$4:$J$11,A9,'06.08'!$K$4:$K$11)+SUMIF('06.08'!$L$4:$L$11,A9,'06.08'!$M$4:$M$11)+SUMIF('06.08'!$N$4:$N$11,A9,'06.08'!$O$4:$O$11) -> 0 | N9: =SUMIF('07.08'!$B$4:$B$11,A9,'07.08'!$C$4:$C$11)+SUMIF('07.08'!$D$4:$D$11,A9,'07.08'!$E$4:$E$11)+SUMIF('07.08'!$F$4:$F$11,A9,'07.08'!$G$4:$G$11)+SUMIF('07.08'!$H$4:$H$11,A9,'07.08'!$I$4:$I$11)+SUMIF('07.08'!$J$4:$J$11,A9,'07.08'!$K$4:$K$11)+SUMIF('07.08'!$L$4:$L$11,A9,'07.08'!$M$4:$M$11)+SUMIF('07.08'!$N$4:$N$11,A9,'07.08'!$O$4:$O$11) -> 0 | O9: =SUMIF('08.08'!$B$4:$B$11,A9,'08.08'!$C$4:$C$11)+SUMIF('08.08'!$D$4:$D$11,A9,'08.08'!$E$4:$E$11)+SUMIF('08.08'!$F$4:$F$11,A9,'08.08'!$G$4:$G$11)+SUMIF('08.08'!$H$4:$H$11,A9,'08.08'!$I$4:$I$11)+SUMIF('08.08'!$J$4:$J$11,A9,'08.08'!$K$4:$K$11)+SUMIF('08.08'!$L$4:$L$11,A9,'08.08'!$M$4:$M$11)+SUMIF('08.08'!$N$4:$N$11,A9,'08.08'!$O$4:$O$11) -> 0 | P9: =SUMIF('09.08'!$B$4:$B$11,A9,'09.08'!$C$4:$C$11)+SUMIF('09.08'!$D$4:$D$11,A9,'09.08'!$E$4:$E$11)+SUMIF('09.08'!$F$4:$F$11,A9,'09.08'!$G$4:$G$11)+SUMIF('09.08'!$H$4:$H$11,A9,'09.08'!$I$4:$I$11)+SUMIF('09.08'!$J$4:$J$11,A9,'09.08'!$K$4:$K$11)+SUMIF('09.08'!$L$4:$L$11,A9,'09.08'!$M$4:$M$11)+SUMIF('09.08'!$N$4:$N$11,A9,'09.08'!$O$4:$O$11) -> 0 | Q9: =SUMIF('10.08'!$B$4:$B$11,A9,'10.08'!$C$4:$C$11)+SUMIF('10.08'!$D$4:$D$11,A9,'10.08'!$E$4:$E$11)+SUMIF('10.08'!$F$4:$F$11,A9,'10.08'!$G$4:$G$11)+SUMIF('10.08'!$H$4:$H$11,A9,'10.08'!$I$4:$I$11)+SUMIF('10.08'!$J$4:$J$11,A9,'10.08'!$K$4:$K$11)+SUMIF('10.08'!$L$4:$L$11,A9,'10.08'!$M$4:$M$11)+SUMIF('10.08'!$N$4:$N$11,A9,'10.08'!$O$4:$O$11) -> 0 | R9: =SUMIF('11.08'!$B$4:$B$11,A9,'11.08'!$C$4:$C$11)+SUMIF('11.08'!$D$4:$D$11,A9,'11.08'!$E$4:$E$11)+SUMIF('11.08'!$F$4:$F$11,A9,'11.08'!$G$4:$G$11)+SUMIF('11.08'!$H$4:$H$11,A9,'11.08'!$I$4:$I$11)+SUMIF('11.08'!$J$4:$J$11,A9,'11.08'!$K$4:$K$11)+SUMIF('11.08'!$L$4:$L$11,A9,'11.08'!$M$4:$M$11)+SUMIF('11.08'!$N$4:$N$11,A9,'11.08'!$O$4:$O$11) -> #N/A
A10: ='список продуктов'!A12 -> Джем | B10: ='список продуктов'!B12 -> пачка | C10: ='список продуктов'!C12 | D10: ='список продуктов'!D12 | E10: ='список продуктов'!E12 -> Долгосрочный | F10: =SUM(I10:R10) -> #N/A | G10: =IFERROR(CEILING(F10/C10,1),"Введите занчения") -> Введите занчения | H10: =IFERROR(G10*D10,"Введите занчения") -> Введите занчения | I10: =SUMIF('02.08'!$B$4:$B$11,A10,'02.08'!$C$4:$C$11)+SUMIF('02.08'!$D$4:$D$11,A10,'02.08'!$E$4:$E$11)+SUMIF('02.08'!$F$4:$F$11,A10,'02.08'!$G$4:$G$11)+SUMIF('02.08'!$H$4:$H$11,A10,'02.08'!$I$4:$I$11)+SUMIF('02.08'!$J$4:$J$11,A10,'02.08'!$K$4:$K$11)+SUMIF('02.08'!$L$4:$L$11,A10,'02.08'!$M$4:$M$11)+SUMIF('02.08'!$N$4:$N$11,A10,'02.08'!$O$4:$O$11) -> 0 | J10: =SUMIF('03.08'!$B$4:$B$11,A10,'03.08'!$C$4:$C$11)+SUMIF('03.08'!$D$4:$D$11,A10,'03.08'!$E$4:$E$11)+SUMIF('03.08'!$F$4:$F$11,A10,'03.08'!$G$4:$G$11)+SUMIF('03.08'!$H$4:$H$11,A10,'03.08'!$I$4:$I$11)+SUMIF('03.08'!$J$4:$J$11,A10,'03.08'!$K$4:$K$11)+SUMIF('03.08'!$L$4:$L$11,A10,'03.08'!$M$4:$M$11)+SUMIF('03.08'!$N$4:$N$11,A10,'03.08'!$O$4:$O$11) -> 0 | K10: =SUMIF('04.08'!$B$4:$B$11,A10,'04.08'!$C$4:$C$11)+SUMIF('04.08'!$D$4:$D$11,A10,'04.08'!$E$4:$E$11)+SUMIF('04.08'!$F$4:$F$11,A10,'04.08'!$G$4:$G$11)+SUMIF('04.08'!$H$4:$H$11,A10,'04.08'!$I$4:$I$11)+SUMIF('04.08'!$J$4:$J$11,A10,'04.08'!$K$4:$K$11)+SUMIF('04.08'!$L$4:$L$11,A10,'04.08'!$M$4:$M$11)+SUMIF('04.08'!$N$4:$N$11,A10,'04.08'!$O$4:$O$11) -> 0 | L10: =SUMIF('05.08'!$B$4:$B$11,A10,'05.08'!$C$4:$C$11)+SUMIF('05.08'!$D$4:$D$11,A10,'05.08'!$E$4:$E$11)+SUMIF('05.08'!$F$4:$F$11,A10,'05.08'!$G$4:$G$11)+SUMIF('05.08'!$H$4:$H$11,A10,'05.08'!$I$4:$I$11)+SUMIF('05.08'!$J$4:$J$11,A10,'05.08'!$K$4:$K$11)+SUMIF('05.08'!$L$4:$L$11,A10,'05.08'!$M$4:$M$11)+SUMIF('05.08'!$N$4:$N$11,A10,'05.08'!$O$4:$O$11) -> 0 | M10: =SUMIF('06.08'!$B$4:$B$11,A10,'06.08'!$C$4:$C$11)+SUMIF('06.08'!$D$4:$D$11,A10,'06.08'!$E$4:$E$11)+SUMIF('06.08'!$F$4:$F$11,A10,'06.08'!$G$4:$G$11)+SUMIF('06.08'!$H$4:$H$11,A10,'06.08'!$I$4:$I$11)+SUMIF('06.08'!$J$4:$J$11,A10,'06.08'!$K$4:$K$11)+SUMIF('06.08'!$L$4:$L$11,A10,'06.08'!$M$4:$M$11)+SUMIF('06.08'!$N$4:$N$11,A10,'06.08'!$O$4:$O$11) -> 0 | N10: =SUMIF('07.08'!$B$4:$B$11,A10,'07.08'!$C$4:$C$11)+SUMIF('07.08'!$D$4:$D$11,A10,'07.08'!$E$4:$E$11)+SUMIF('07.08'!$F$4:$F$11,A10,'07.08'!$G$4:$G$11)+SUMIF('07.08'!$H$4:$H$11,A10,'07.08'!$I$4:$I$11)+SUMIF('07.08'!$J$4:$J$11,A10,'07.08'!$K$4:$K$11)+SUMIF('07.08'!$L$4:$L$11,A10,'07.08'!$M$4:$M$11)+SUMIF('07.08'!$N$4:$N$11,A10,'07.08'!$O$4:$O$11) -> 0 | O10: =SUMIF('08.08'!$B$4:$B$11,A10,'08.08'!$C$4:$C$11)+SUMIF('08.08'!$D$4:$D$11,A10,'08.08'!$E$4:$E$11)+SUMIF('08.08'!$F$4:$F$11,A10,'08.08'!$G$4:$G$11)+SUMIF('08.08'!$H$4:$H$11,A10,'08.08'!$I$4:$I$11)+SUMIF('08.08'!$J$4:$J$11,A10,'08.08'!$K$4:$K$11)+SUMIF('08.08'!$L$4:$L$11,A10,'08.08'!$M$4:$M$11)+SUMIF('08.08'!$N$4:$N$11,A10,'08.08'!$O$4:$O$11) -> 0 | P10: =SUMIF('09.08'!$B$4:$B$11,A10,'09.08'!$C$4:$C$11)+SUMIF('09.08'!$D$4:$D$11,A10,'09.08'!$E$4:$E$11)+SUMIF('09.08'!$F$4:$F$11,A10,'09.08'!$G$4:$G$11)+SUMIF('09.08'!$H$4:$H$11,A10,'09.08'!$I$4:$I$11)+SUMIF('09.08'!$J$4:$J$11,A10,'09.08'!$K$4:$K$11)+SUMIF('09.08'!$L$4:$L$11,A10,'09.08'!$M$4:$M$11)+SUMIF('09.08'!$N$4:$N$11,A10,'09.08'!$O$4:$O$11) -> 0 | Q10: =SUMIF('10.08'!$B$4:$B$11,A10,'10.08'!$C$4:$C$11)+SUMIF('10.08'!$D$4:$D$11,A10,'10.08'!$E$4:$E$11)+SUMIF('10.08'!$F$4:$F$11,A10,'10.08'!$G$4:$G$11)+SUMIF('10.08'!$H$4:$H$11,A10,'10.08'!$I$4:$I$11)+SUMIF('10.08'!$J$4:$J$11,A10,'10.08'!$K$4:$K$11)+SUMIF('10.08'!$L$4:$L$11,A10,'10.08'!$M$4:$M$11)+SUMIF('10.08'!$N$4:$N$11,A10,'10.08'!$O$4:$O$11) -> 0 | R10: =SUMIF('11.08'!$B$4:$B$11,A10,'11.08'!$C$4:$C$11)+SUMIF('11.08'!$D$4:$D$11,A10,'11.08'!$E$4:$E$11)+SUMIF('11.08'!$F$4:$F$11,A10,'11.08'!$G$4:$G$11)+SUMIF('11.08'!$H$4:$H$11,A10,'11.08'!$I$4:$I$11)+SUMIF('11.08'!$J$4:$J$11,A10,'11.08'!$K$4:$K$11)+SUMIF('11.08'!$L$4:$L$11,A10,'11.08'!$M$4:$M$11)+SUMIF('11.08'!$N$4:$N$11,A10,'11.08'!$O$4:$O$11) -> #N/A
A11: ='список продуктов'!A13 -> Дрожжи | B11: ='список продуктов'!B13 -> пачка | C11: ='список продуктов'!C13 | D11: ='список продуктов'!D13 | E11: ='список продуктов'!E13 -> Долгосрочный | F11: =SUM(I11:R11) -> #N/A | G11: =IFERROR(CEILING(F11/C11,1),"Введите занчения") -> Введите занчения | H11: =IFERROR(G11*D11,"Введите занчения") -> Введите занчения | I11: =SUMIF('02.08'!$B$4:$B$11,A11,'02.08'!$C$4:$C$11)+SUMIF('02.08'!$D$4:$D$11,A11,'02.08'!$E$4:$E$11)+SUMIF('02.08'!$F$4:$F$11,A11,'02.08'!$G$4:$G$11)+SUMIF('02.08'!$H$4:$H$11,A11,'02.08'!$I$4:$I$11)+SUMIF('02.08'!$J$4:$J$11,A11,'02.08'!$K$4:$K$11)+SUMIF('02.08'!$L$4:$L$11,A11,'02.08'!$M$4:$M$11)+SUMIF('02.08'!$N$4:$N$11,A11,'02.08'!$O$4:$O$11) -> 0 | J11: =SUMIF('03.08'!$B$4:$B$11,A11,'03.08'!$C$4:$C$11)+SUMIF('03.08'!$D$4:$D$11,A11,'03.08'!$E$4:$E$11)+SUMIF('03.08'!$F$4:$F$11,A11,'03.08'!$G$4:$G$11)+SUMIF('03.08'!$H$4:$H$11,A11,'03.08'!$I$4:$I$11)+SUMIF('03.08'!$J$4:$J$11,A11,'03.08'!$K$4:$K$11)+SUMIF('03.08'!$L$4:$L$11,A11,'03.08'!$M$4:$M$11)+SUMIF('03.08'!$N$4:$N$11,A11,'03.08'!$O$4:$O$11) -> 0 | K11: =SUMIF('04.08'!$B$4:$B$11,A11,'04.08'!$C$4:$C$11)+SUMIF('04.08'!$D$4:$D$11,A11,'04.08'!$E$4:$E$11)+SUMIF('04.08'!$F$4:$F$11,A11,'04.08'!$G$4:$G$11)+SUMIF('04.08'!$H$4:$H$11,A11,'04.08'!$I$4:$I$11)+SUMIF('04.08'!$J$4:$J$11,A11,'04.08'!$K$4:$K$11)+SUMIF('04.08'!$L$4:$L$11,A11,'04.08'!$M$4:$M$11)+SUMIF('04.08'!$N$4:$N$11,A11,'04.08'!$O$4:$O$11) -> 0 | L11: =SUMIF('05.08'!$B$4:$B$11,A11,'05.08'!$C$4:$C$11)+SUMIF('05.08'!$D$4:$D$11,A11,'05.08'!$E$4:$E$11)+SUMIF('05.08'!$F$4:$F$11,A11,'05.08'!$G$4:$G$11)+SUMIF('05.08'!$H$4:$H$11,A11,'05.08'!$I$4:$I$11)+SUMIF('05.08'!$J$4:$J$11,A11,'05.08'!$K$4:$K$11)+SUMIF('05.08'!$L$4:$L$11,A11,'05.08'!$M$4:$M$11)+SUMIF('05.08'!$N$4:$N$11,A11,'05.08'!$O$4:$O$11) -> 0 | M11: =SUMIF('06.08'!$B$4:$B$11,A11,'06.08'!$C$4:$C$11)+SUMIF('06.08'!$D$4:$D$11,A11,'06.08'!$E$4:$E$11)+SUMIF('06.08'!$F$4:$F$11,A11,'06.08'!$G$4:$G$11)+SUMIF('06.08'!$H$4:$H$11,A11,'06.08'!$I$4:$I$11)+SUMIF('06.08'!$J$4:$J$11,A11,'06.08'!$K$4:$K$11)+SUMIF('06.08'!$L$4:$L$11,A11,'06.08'!$M$4:$M$11)+SUMIF('06.08'!$N$4:$N$11,A11,'06.08'!$O$4:$O$11) -> 0 | N11: =SUMIF('07.08'!$B$4:$B$11,A11,'07.08'!$C$4:$C$11)+SUMIF('07.08'!$D$4:$D$11,A11,'07.08'!$E$4:$E$11)+SUMIF('07.08'!$F$4:$F$11,A11,'07.08'!$G$4:$G$11)+SUMIF('07.08'!$H$4:$H$11,A11,'07.08'!$I$4:$I$11)+SUMIF('07.08'!$J$4:$J$11,A11,'07.08'!$K$4:$K$11)+SUMIF('07.08'!$L$4:$L$11,A11,'07.08'!$M$4:$M$11)+SUMIF('07.08'!$N$4:$N$11,A11,'07.08'!$O$4:$O$11) -> 0 | O11: =SUMIF('08.08'!$B$4:$B$11,A11,'08.08'!$C$4:$C$11)+SUMIF('08.08'!$D$4:$D$11,A11,'08.08'!$E$4:$E$11)+SUMIF('08.08'!$F$4:$F$11,A11,'08.08'!$G$4:$G$11)+SUMIF('08.08'!$H$4:$H$11,A11,'08.08'!$I$4:$I$11)+SUMIF('08.08'!$J$4:$J$11,A11,'08.08'!$K$4:$K$11)+SUMIF('08.08'!$L$4:$L$11,A11,'08.08'!$M$4:$M$11)+SUMIF('08.08'!$N$4:$N$11,A11,'08.08'!$O$4:$O$11) -> 0 | P11: =SUMIF('09.08'!$B$4:$B$11,A11,'09.08'!$C$4:$C$11)+SUMIF('09.08'!$D$4:$D$11,A11,'09.08'!$E$4:$E$11)+SUMIF('09.08'!$F$4:$F$11,A11,'09.08'!$G$4:$G$11)+SUMIF('09.08'!$H$4:$H$11,A11,'09.08'!$I$4:$I$11)+SUMIF('09.08'!$J$4:$J$11,A11,'09.08'!$K$4:$K$11)+SUMIF('09.08'!$L$4:$L$11,A11,'09.08'!$M$4:$M$11)+SUMIF('09.08'!$N$4:$N$11,A11,'09.08'!$O$4:$O$11) -> 0 | Q11: =SUMIF('10.08'!$B$4:$B$11,A11,'10.08'!$C$4:$C$11)+SUMIF('10.08'!$D$4:$D$11,A11,'10.08'!$E$4:$E$11)+SUMIF('10.08'!$F$4:$F$11,A11,'10.08'!$G$4:$G$11)+SUMIF('10.08'!$H$4:$H$11,A11,'10.08'!$I$4:$I$11)+SUMIF('10.08'!$J$4:$J$11,A11,'10.08'!$K$4:$K$11)+SUMIF('10.08'!$L$4:$L$11,A11,'10.08'!$M$4:$M$11)+SUMIF('10.08'!$N$4:$N$11,A11,'10.08'!$O$4:$O$11) -> 0 | R11: =SUMIF('11.08'!$B$4:$B$11,A11,'11.08'!$C$4:$C$11)+SUMIF('11.08'!$D$4:$D$11,A11,'11.08'!$E$4:$E$11)+SUMIF('11.08'!$F$4:$F$11,A11,'11.08'!$G$4:$G$11)+SUMIF('11.08'!$H$4:$H$11,A11,'11.08'!$I$4:$I$11)+SUMIF('11.08'!$J$4:$J$11,A11,'11.08'!$K$4:$K$11)+SUMIF('11.08'!$L$4:$L$11,A11,'11.08'!$M$4:$M$11)+SUMIF('11.08'!$N$4:$N$11,A11,'11.08'!$O$4:$O$11) -> #N/A
A12: ='список продуктов'!A14 -> Заготовка для супа сухая | B12: ='список продуктов'!B14 -> пачка | C12: ='список продуктов'!C14 | D12: ='список продуктов'!D14 | E12: ='список продуктов'!E14 -> Долгосрочный | F12: =SUM(I12:R12) -> #N/A | G12: =IFERROR(CEILING(F12/C12,1),"Введите занчения") -> Введите занчения | H12: =IFERROR(G12*D12,"Введите занчения") -> Введите занчения | I12: =SUMIF('02.08'!$B$4:$B$11,A12,'02.08'!$C$4:$C$11)+SUMIF('02.08'!$D$4:$D$11,A12,'02.08'!$E$4:$E$11)+SUMIF('02.08'!$F$4:$F$11,A12,'02.08'!$G$4:$G$11)+SUMIF('02.08'!$H$4:$H$11,A12,'02.08'!$I$4:$I$11)+SUMIF('02.08'!$J$4:$J$11,A12,'02.08'!$K$4:$K$11)+SUMIF('02.08'!$L$4:$L$11,A12,'02.08'!$M$4:$M$11)+SUMIF('02.08'!$N$4:$N$11,A12,'02.08'!$O$4:$O$11) -> 0 | J12: =SUMIF('03.08'!$B$4:$B$11,A12,'03.08'!$C$4:$C$11)+SUMIF('03.08'!$D$4:$D$11,A12,'03.08'!$E$4:$E$11)+SUMIF('03.08'!$F$4:$F$11,A12,'03.08'!$G$4:$G$11)+SUMIF('03.08'!$H$4:$H$11,A12,'03.08'!$I$4:$I$11)+SUMIF('03.08'!$J$4:$J$11,A12,'03.08'!$K$4:$K$11)+SUMIF('03.08'!$L$4:$L$11,A12,'03.08'!$M$4:$M$11)+SUMIF('03.08'!$N$4:$N$11,A12,'03.08'!$O$4:$O$11) -> 0 | K12: =SUMIF('04.08'!$B$4:$B$11,A12,'04.08'!$C$4:$C$11)+SUMIF('04.08'!$D$4:$D$11,A12,'04.08'!$E$4:$E$11)+SUMIF('04.08'!$F$4:$F$11,A12,'04.08'!$G$4:$G$11)+SUMIF('04.08'!$H$4:$H$11,A12,'04.08'!$I$4:$I$11)+SUMIF('04.08'!$J$4:$J$11,A12,'04.08'!$K$4:$K$11)+SUMIF('04.08'!$L$4:$L$11,A12,'04.08'!$M$4:$M$11)+SUMIF('04.08'!$N$4:$N$11,A12,'04.08'!$O$4:$O$11) -> 0 | L12: =SUMIF('05.08'!$B$4:$B$11,A12,'05.08'!$C$4:$C$11)+SUMIF('05.08'!$D$4:$D$11,A12,'05.08'!$E$4:$E$11)+SUMIF('05.08'!$F$4:$F$11,A12,'05.08'!$G$4:$G$11)+SUMIF('05.08'!$H$4:$H$11,A12,'05.08'!$I$4:$I$11)+SUMIF('05.08'!$J$4:$J$11,A12,'05.08'!$K$4:$K$11)+SUMIF('05.08'!$L$4:$L$11,A12,'05.08'!$M$4:$M$11)+SUMIF('05.08'!$N$4:$N$11,A12,'05.08'!$O$4:$O$11) -> 0 | M12: =SUMIF('06.08'!$B$4:$B$11,A12,'06.08'!$C$4:$C$11)+SUMIF('06.08'!$D$4:$D$11,A12,'06.08'!$E$4:$E$11)+SUMIF('06.08'!$F$4:$F$11,A12,'06.08'!$G$4:$G$11)+SUMIF('06.08'!$H$4:$H$11,A12,'06.08'!$I$4:$I$11)+SUMIF('06.08'!$J$4:$J$11,A12,'06.08'!$K$4:$K$11)+SUMIF('06.08'!$L$4:$L$11,A12,'06.08'!$M$4:$M$11)+SUMIF('06.08'!$N$4:$N$11,A12,'06.08'!$O$4:$O$11) -> 0 | N12: =SUMIF('07.08'!$B$4:$B$11,A12,'07.08'!$C$4:$C$11)+SUMIF('07.08'!$D$4:$D$11,A12,'07.08'!$E$4:$E$11)+SUMIF('07.08'!$F$4:$F$11,A12,'07.08'!$G$4:$G$11)+SUMIF('07.08'!$H$4:$H$11,A12,'07.08'!$I$4:$I$11)+SUMIF('07.08'!$J$4:$J$11,A12,'07.08'!$K$4:$K$11)+SUMIF('07.08'!$L$4:$L$11,A12,'07.08'!$M$4:$M$11)+SUMIF('07.08'!$N$4:$N$11,A12,'07.08'!$O$4:$O$11) -> 0 | O12: =SUMIF('08.08'!$B$4:$B$11,A12,'08.08'!$C$4:$C$11)+SUMIF('08.08'!$D$4:$D$11,A12,'08.08'!$E$4:$E$11)+SUMIF('08.08'!$F$4:$F$11,A12,'08.08'!$G$4:$G$11)+SUMIF('08.08'!$H$4:$H$11,A12,'08.08'!$I$4:$I$11)+SUMIF('08.08'!$J$4:$J$11,A12,'08.08'!$K$4:$K$11)+SUMIF('08.08'!$L$4:$L$11,A12,'08.08'!$M$4:$M$11)+SUMIF('08.08'!$N$4:$N$11,A12,'08.08'!$O$4:$O$11) -> 0 | P12: =SUMIF('09.08'!$B$4:$B$11,A12,'09.08'!$C$4:$C$11)+SUMIF('09.08'!$D$4:$D$11,A12,'09.08'!$E$4:$E$11)+SUMIF('09.08'!$F$4:$F$11,A12,'09.08'!$G$4:$G$11)+SUMIF('09.08'!$H$4:$H$11,A12,'09.08'!$I$4:$I$11)+SUMIF('09.08'!$J$4:$J$11,A12,'09.08'!$K$4:$K$11)+SUMIF('09.08'!$L$4:$L$11,A12,'09.08'!$M$4:$M$11)+SUMIF('09.08'!$N$4:$N$11,A12,'09.08'!$O$4:$O$11) -> 0 | Q12: =SUMIF('10.08'!$B$4:$B$11,A12,'10.08'!$C$4:$C$11)+SUMIF('10.08'!$D$4:$D$11,A12,'10.08'!$E$4:$E$11)+SUMIF('10.08'!$F$4:$F$11,A12,'10.08'!$G$4:$G$11)+SUMIF('10.08'!$H$4:$H$11,A12,'10.08'!$I$4:$I$11)+SUMIF('10.08'!$J$4:$J$11,A12,'10.08'!$K$4:$K$11)+SUMIF('10.08'!$L$4:$L$11,A12,'10.08'!$M$4:$M$11)+SUMIF('10.08'!$N$4:$N$11,A12,'10.08'!$O$4:$O$11) -> 0 | R12: =SUMIF('11.08'!$B$4:$B$11,A12,'11.08'!$C$4:$C$11)+SUMIF('11.08'!$D$4:$D$11,A12,'11.08'!$E$4:$E$11)+SUMIF('11.08'!$F$4:$F$11,A12,'11.08'!$G$4:$G$11)+SUMIF('11.08'!$H$4:$H$11,A12,'11.08'!$I$4:$I$11)+SUMIF('11.08'!$J$4:$J$11,A12,'11.08'!$K$4:$K$11)+SUMIF('11.08'!$L$4:$L$11,A12,'11.08'!$M$4:$M$11)+SUMIF('11.08'!$N$4:$N$11,A12,'11.08'!$O$4:$O$11) -> #N/A
A13: ='список продуктов'!A16 -> Кабачки | B13: ='список продуктов'!B16 -> кг | C13: ='список продуктов'!C16 -> 1000 | D13: ='список продуктов'!D16 | E13: ='список продуктов'!E16 -> Краткосрочный | F13: =SUM(I13:R13) -> #N/A | G13: =IFERROR(CEILING(F13/C13,1),"Введите занчения") -> Введите занчения | H13: =IFERROR(G13*D13,"Введите занчения") -> Введите занчения | I13: =SUMIF('02.08'!$B$4:$B$11,A13,'02.08'!$C$4:$C$11)+SUMIF('02.08'!$D$4:$D$11,A13,'02.08'!$E$4:$E$11)+SUMIF('02.08'!$F$4:$F$11,A13,'02.08'!$G$4:$G$11)+SUMIF('02.08'!$H$4:$H$11,A13,'02.08'!$I$4:$I$11)+SUMIF('02.08'!$J$4:$J$11,A13,'02.08'!$K$4:$K$11)+SUMIF('02.08'!$L$4:$L$11,A13,'02.08'!$M$4:$M$11)+SUMIF('02.08'!$N$4:$N$11,A13,'02.08'!$O$4:$O$11) -> 0 | J13: =SUMIF('03.08'!$B$4:$B$11,A13,'03.08'!$C$4:$C$11)+SUMIF('03.08'!$D$4:$D$11,A13,'03.08'!$E$4:$E$11)+SUMIF('03.08'!$F$4:$F$11,A13,'03.08'!$G$4:$G$11)+SUMIF('03.08'!$H$4:$H$11,A13,'03.08'!$I$4:$I$11)+SUMIF('03.08'!$J$4:$J$11,A13,'03.08'!$K$4:$K$11)+SUMIF('03.08'!$L$4:$L$11,A13,'03.08'!$M$4:$M$11)+SUMIF('03.08'!$N$4:$N$11,A13,'03.08'!$O$4:$O$11) -> 0 | K13: =SUMIF('04.08'!$B$4:$B$11,A13,'04.08'!$C$4:$C$11)+SUMIF('04.08'!$D$4:$D$11,A13,'04.08'!$E$4:$E$11)+SUMIF('04.08'!$F$4:$F$11,A13,'04.08'!$G$4:$G$11)+SUMIF('04.08'!$H$4:$H$11,A13,'04.08'!$I$4:$I$11)+SUMIF('04.08'!$J$4:$J$11,A13,'04.08'!$K$4:$K$11)+SUMIF('04.08'!$L$4:$L$11,A13,'04.08'!$M$4:$M$11)+SUMIF('04.08'!$N$4:$N$11,A13,'04.08'!$O$4:$O$11) -> 0 | L13: =SUMIF('05.08'!$B$4:$B$11,A13,'05.08'!$C$4:$C$11)+SUMIF('05.08'!$D$4:$D$11,A13,'05.08'!$E$4:$E$11)+SUMIF('05.08'!$F$4:$F$11,A13,'05.08'!$G$4:$G$11)+SUMIF('05.08'!$H$4:$H$11,A13,'05.08'!$I$4:$I$11)+SUMIF('05.08'!$J$4:$J$11,A13,'05.08'!$K$4:$K$11)+SUMIF('05.08'!$L$4:$L$11,A13,'05.08'!$M$4:$M$11)+SUMIF('05.08'!$N$4:$N$11,A13,'05.08'!$O$4:$O$11) -> 0 | M13: =SUMIF('06.08'!$B$4:$B$11,A13,'06.08'!$C$4:$C$11)+SUMIF('06.08'!$D$4:$D$11,A13,'06.08'!$E$4:$E$11)+SUMIF('06.08'!$F$4:$F$11,A13,'06.08'!$G$4:$G$11)+SUMIF('06.08'!$H$4:$H$11,A13,'06.08'!$I$4:$I$11)+SUMIF('06.08'!$J$4:$J$11,A13,'06.08'!$K$4:$K$11)+SUMIF('06.08'!$L$4:$L$11,A13,'06.08'!$M$4:$M$11)+SUMIF('06.08'!$N$4:$N$11,A13,'06.08'!$O$4:$O$11) -> 0 | N13: =SUMIF('07.08'!$B$4:$B$11,A13,'07.08'!$C$4:$C$11)+SUMIF('07.08'!$D$4:$D$11,A13,'07.08'!$E$4:$E$11)+SUMIF('07.08'!$F$4:$F$11,A13,'07.08'!$G$4:$G$11)+SUMIF('07.08'!$H$4:$H$11,A13,'07.08'!$I$4:$I$11)+SUMIF('07.08'!$J$4:$J$11,A13,'07.08'!$K$4:$K$11)+SUMIF('07.08'!$L$4:$L$11,A13,'07.08'!$M$4:$M$11)+SUMIF('07.08'!$N$4:$N$11,A13,'07.08'!$O$4:$O$11) -> 0 | O13: =SUMIF('08.08'!$B$4:$B$11,A13,'08.08'!$C$4:$C$11)+SUMIF('08.08'!$D$4:$D$11,A13,'08.08'!$E$4:$E$11)+SUMIF('08.08'!$F$4:$F$11,A13,'08.08'!$G$4:$G$11)+SUMIF('08.08'!$H$4:$H$11,A13,'08.08'!$I$4:$I$11)+SUMIF('08.08'!$J$4:$J$11,A13,'08.08'!$K$4:$K$11)+SUMIF('08.08'!$L$4:$L$11,A13,'08.08'!$M$4:$M$11)+SUMIF('08.08'!$N$4:$N$11,A13,'08.08'!$O$4:$O$11) -> 0 | P13: =SUMIF('09.08'!$B$4:$B$11,A13,'09.08'!$C$4:$C$11)+SUMIF('09.08'!$D$4:$D$11,A13,'09.08'!$E$4:$E$11)+SUMIF('09.08'!$F$4:$F$11,A13,'09.08'!$G$4:$G$11)+SUMIF('09.08'!$H$4:$H$11,A13,'09.08'!$I$4:$I$11)+SUMIF('09.08'!$J$4:$J$11,A13,'09.08'!$K$4:$K$11)+SUMIF('09.08'!$L$4:$L$11,A13,'09.08'!$M$4:$M$11)+SUMIF('09.08'!$N$4:$N$11,A13,'09.08'!$O$4:$O$11) -> 0 | Q13: =SUMIF('10.08'!$B$4:$B$11,A13,'10.08'!$C$4:$C$11)+SUMIF('10.08'!$D$4:$D$11,A13,'10.08'!$E$4:$E$11)+SUMIF('10.08'!$F$4:$F$11,A13,'10.08'!$G$4:$G$11)+SUMIF('10.08'!$H$4:$H$11,A13,'10.08'!$I$4:$I$11)+SUMIF('10.08'!$J$4:$J$11,A13,'10.08'!$K$4:$K$11)+SUMIF('10.08'!$L$4:$L$11,A13,'10.08'!$M$4:$M$11)+SUMIF('10.08'!$N$4:$N$11,A13,'10.08'!$O$4:$O$11) -> 0 | R13: =SUMIF('11.08'!$B$4:$B$11,A13,'11.08'!$C$4:$C$11)+SUMIF('11.08'!$D$4:$D$11,A13,'11.08'!$E$4:$E$11)+SUMIF('11.08'!$F$4:$F$11,A13,'11.08'!$G$4:$G$11)+SUMIF('11.08'!$H$4:$H$11,A13,'11.08'!$I$4:$I$11)+SUMIF('11.08'!$J$4:$J$11,A13,'11.08'!$K$4:$K$11)+SUMIF('11.08'!$L$4:$L$11,A13,'11.08'!$M$4:$M$11)+SUMIF('11.08'!$N$4:$N$11,A13,'11.08'!$O$4:$O$11) -> #N/A
A14: ='список продуктов'!A17 -> Капуста | B14: ='список продуктов'!B17 -> кг | C14: ='список продуктов'!C17 -> 1000 | D14: ='список продуктов'!D17 | E14: ='список продуктов'!E17 -> Краткосрочный | F14: =SUM(I14:R14) -> #N/A | G14: =IFERROR(CEILING(F14/C14,1),"Введите занчения") -> Введите занчения | H14: =IFERROR(G14*D14,"Введите занчения") -> Введите занчения | I14: =SUMIF('02.08'!$B$4:$B$11,A14,'02.08'!$C$4:$C$11)+SUMIF('02.08'!$D$4:$D$11,A14,'02.08'!$E$4:$E$11)+SUMIF('02.08'!$F$4:$F$11,A14,'02.08'!$G$4:$G$11)+SUMIF('02.08'!$H$4:$H$11,A14,'02.08'!$I$4:$I$11)+SUMIF('02.08'!$J$4:$J$11,A14,'02.08'!$K$4:$K$11)+SUMIF('02.08'!$L$4:$L$11,A14,'02.08'!$M$4:$M$11)+SUMIF('02.08'!$N$4:$N$11,A14,'02.08'!$O$4:$O$11) -> 0 | J14: =SUMIF('03.08'!$B$4:$B$11,A14,'03.08'!$C$4:$C$11)+SUMIF('03.08'!$D$4:$D$11,A14,'03.08'!$E$4:$E$11)+SUMIF('03.08'!$F$4:$F$11,A14,'03.08'!$G$4:$G$11)+SUMIF('03.08'!$H$4:$H$11,A14,'03.08'!$I$4:$I$11)+SUMIF('03.08'!$J$4:$J$11,A14,'03.08'!$K$4:$K$11)+SUMIF('03.08'!$L$4:$L$11,A14,'03.08'!$M$4:$M$11)+SUMIF('03.08'!$N$4:$N$11,A14,'03.08'!$O$4:$O$11) -> 0 | K14: =SUMIF('04.08'!$B$4:$B$11,A14,'04.08'!$C$4:$C$11)+SUMIF('04.08'!$D$4:$D$11,A14,'04.08'!$E$4:$E$11)+SUMIF('04.08'!$F$4:$F$11,A14,'04.08'!$G$4:$G$11)+SUMIF('04.08'!$H$4:$H$11,A14,'04.08'!$I$4:$I$11)+SUMIF('04.08'!$J$4:$J$11,A14,'04.08'!$K$4:$K$11)+SUMIF('04.08'!$L$4:$L$11,A14,'04.08'!$M$4:$M$11)+SUMIF('04.08'!$N$4:$N$11,A14,'04.08'!$O$4:$O$11) -> 0 | L14: =SUMIF('05.08'!$B$4:$B$11,A14,'05.08'!$C$4:$C$11)+SUMIF('05.08'!$D$4:$D$11,A14,'05.08'!$E$4:$E$11)+SUMIF('05.08'!$F$4:$F$11,A14,'05.08'!$G$4:$G$11)+SUMIF('05.08'!$H$4:$H$11,A14,'05.08'!$I$4:$I$11)+SUMIF('05.08'!$J$4:$J$11,A14,'05.08'!$K$4:$K$11)+SUMIF('05.08'!$L$4:$L$11,A14,'05.08'!$M$4:$M$11)+SUMIF('05.08'!$N$4:$N$11,A14,'05.08'!$O$4:$O$11) -> 0 | M14: =SUMIF('06.08'!$B$4:$B$11,A14,'06.08'!$C$4:$C$11)+SUMIF('06.08'!$D$4:$D$11,A14,'06.08'!$E$4:$E$11)+SUMIF('06.08'!$F$4:$F$11,A14,'06.08'!$G$4:$G$11)+SUMIF('06.08'!$H$4:$H$11,A14,'06.08'!$I$4:$I$11)+SUMIF('06.08'!$J$4:$J$11,A14,'06.08'!$K$4:$K$11)+SUMIF('06.08'!$L$4:$L$11,A14,'06.08'!$M$4:$M$11)+SUMIF('06.08'!$N$4:$N$11,A14,'06.08'!$O$4:$O$11) -> 0 | N14: =SUMIF('07.08'!$B$4:$B$11,A14,'07.08'!$C$4:$C$11)+SUMIF('07.08'!$D$4:$D$11,A14,'07.08'!$E$4:$E$11)+SUMIF('07.08'!$F$4:$F$11,A14,'07.08'!$G$4:$G$11)+SUMIF('07.08'!$H$4:$H$11,A14,'07.08'!$I$4:$I$11)+SUMIF('07.08'!$J$4:$J$11,A14,'07.08'!$K$4:$K$11)+SUMIF('07.08'!$L$4:$L$11,A14,'07.08'!$M$4:$M$11)+SUMIF('07.08'!$N$4:$N$11,A14,'07.08'!$O$4:$O$11) -> 0 | O14: =SUMIF('08.08'!$B$4:$B$11,A14,'08.08'!$C$4:$C$11)+SUMIF('08.08'!$D$4:$D$11,A14,'08.08'!$E$4:$E$11)+SUMIF('08.08'!$F$4:$F$11,A14,'08.08'!$G$4:$G$11)+SUMIF('08.08'!$H$4:$H$11,A14,'08.08'!$I$4:$I$11)+SUMIF('08.08'!$J$4:$J$11,A14,'08.08'!$K$4:$K$11)+SUMIF('08.08'!$L$4:$L$11,A14,'08.08'!$M$4:$M$11)+SUMIF('08.08'!$N$4:$N$11,A14,'08.08'!$O$4:$O$11) -> 0 | P14: =SUMIF('09.08'!$B$4:$B$11,A14,'09.08'!$C$4:$C$11)+SUMIF('09.08'!$D$4:$D$11,A14,'09.08'!$E$4:$E$11)+SUMIF('09.08'!$F$4:$F$11,A14,'09.08'!$G$4:$G$11)+SUMIF('09.08'!$H$4:$H$11,A14,'09.08'!$I$4:$I$11)+SUMIF('09.08'!$J$4:$J$11,A14,'09.08'!$K$4:$K$11)+SUMIF('09.08'!$L$4:$L$11,A14,'09.08'!$M$4:$M$11)+SUMIF('09.08'!$N$4:$N$11,A14,'09.08'!$O$4:$O$11) -> 0 | Q14: =SUMIF('10.08'!$B$4:$B$11,A14,'10.08'!$C$4:$C$11)+SUMIF('10.08'!$D$4:$D$11,A14,'10.08'!$E$4:$E$11)+SUMIF('10.08'!$F$4:$F$11,A14,'10.08'!$G$4:$G$11)+SUMIF('10.08'!$H$4:$H$11,A14,'10.08'!$I$4:$I$11)+SUMIF('10.08'!$J$4:$J$11,A14,'10.08'!$K$4:$K$11)+SUMIF('10.08'!$L$4:$L$11,A14,'10.08'!$M$4:$M$11)+SUMIF('10.08'!$N$4:$N$11,A14,'10.08'!$O$4:$O$11) -> 0 | R14: =SUMIF('11.08'!$B$4:$B$11,A14,'11.08'!$C$4:$C$11)+SUMIF('11.08'!$D$4:$D$11,A14,'11.08'!$E$4:$E$11)+SUMIF('11.08'!$F$4:$F$11,A14,'11.08'!$G$4:$G$11)+SUMIF('11.08'!$H$4:$H$11,A14,'11.08'!$I$4:$I$11)+SUMIF('11.08'!$J$4:$J$11,A14,'11.08'!$K$4:$K$11)+SUMIF('11.08'!$L$4:$L$11,A14,'11.08'!$M$4:$M$11)+SUMIF('11.08'!$N$4:$N$11,A14,'11.08'!$O$4:$O$11) -> #N/A
A15: ='список продуктов'!A18 -> Картофель | B15: ='список продуктов'!B18 -> кг | C15: ='список продуктов'!C18 -> 1000 | D15: ='список продуктов'!D18 | E15: ='список продуктов'!E18 -> Краткосрочный | F15: =SUM(I15:R15) -> #N/A | G15: =IFERROR(CEILING(F15/C15,1),"Введите занчения") -> Введите занчения | H15: =IFERROR(G15*D15,"Введите занчения") -> Введите занчения | I15: =SUMIF('02.08'!$B$4:$B$11,A15,'02.08'!$C$4:$C$11)+SUMIF('02.08'!$D$4:$D$11,A15,'02.08'!$E$4:$E$11)+SUMIF('02.08'!$F$4:$F$11,A15,'02.08'!$G$4:$G$11)+SUMIF('02.08'!$H$4:$H$11,A15,'02.08'!$I$4:$I$11)+SUMIF('02.08'!$J$4:$J$11,A15,'02.08'!$K$4:$K$11)+SUMIF('02.08'!$L$4:$L$11,A15,'02.08'!$M$4:$M$11)+SUMIF('02.08'!$N$4:$N$11,A15,'02.08'!$O$4:$O$11) -> 0 | J15: =SUMIF('03.08'!$B$4:$B$11,A15,'03.08'!$C$4:$C$11)+SUMIF('03.08'!$D$4:$D$11,A15,'03.08'!$E$4:$E$11)+SUMIF('03.08'!$F$4:$F$11,A15,'03.08'!$G$4:$G$11)+SUMIF('03.08'!$H$4:$H$11,A15,'03.08'!$I$4:$I$11)+SUMIF('03.08'!$J$4:$J$11,A15,'03.08'!$K$4:$K$11)+SUMIF('03.08'!$L$4:$L$11,A15,'03.08'!$M$4:$M$11)+SUMIF('03.08'!$N$4:$N$11,A15,'03.08'!$O$4:$O$11) -> 0 | K15: =SUMIF('04.08'!$B$4:$B$11,A15,'04.08'!$C$4:$C$11)+SUMIF('04.08'!$D$4:$D$11,A15,'04.08'!$E$4:$E$11)+SUMIF('04.08'!$F$4:$F$11,A15,'04.08'!$G$4:$G$11)+SUMIF('04.08'!$H$4:$H$11,A15,'04.08'!$I$4:$I$11)+SUMIF('04.08'!$J$4:$J$11,A15,'04.08'!$K$4:$K$11)+SUMIF('04.08'!$L$4:$L$11,A15,'04.08'!$M$4:$M$11)+SUMIF('04.08'!$N$4:$N$11,A15,'04.08'!$O$4:$O$11) -> 0 | L15: =SUMIF('05.08'!$B$4:$B$11,A15,'05.08'!$C$4:$C$11)+SUMIF('05.08'!$D$4:$D$11,A15,'05.08'!$E$4:$E$11)+SUMIF('05.08'!$F$4:$F$11,A15,'05.08'!$G$4:$G$11)+SUMIF('05.08'!$H$4:$H$11,A15,'05.08'!$I$4:$I$11)+SUMIF('05.08'!$J$4:$J$11,A15,'05.08'!$K$4:$K$11)+SUMIF('05.08'!$L$4:$L$11,A15,'05.08'!$M$4:$M$11)+SUMIF('05.08'!$N$4:$N$11,A15,'05.08'!$O$4:$O$11) -> 0 | M15: =SUMIF('06.08'!$B$4:$B$11,A15,'06.08'!$C$4:$C$11)+SUMIF('06.08'!$D$4:$D$11,A15,'06.08'!$E$4:$E$11)+SUMIF('06.08'!$F$4:$F$11,A15,'06.08'!$G$4:$G$11)+SUMIF('06.08'!$H$4:$H$11,A15,'06.08'!$I$4:$I$11)+SUMIF('06.08'!$J$4:$J$11,A15,'06.08'!$K$4:$K$11)+SUMIF('06.08'!$L$4:$L$11,A15,'06.08'!$M$4:$M$11)+SUMIF('06.08'!$N$4:$N$11,A15,'06.08'!$O$4:$O$11) -> 0 | N15: =SUMIF('07.08'!$B$4:$B$11,A15,'07.08'!$C$4:$C$11)+SUMIF('07.08'!$D$4:$D$11,A15,'07.08'!$E$4:$E$11)+SUMIF('07.08'!$F$4:$F$11,A15,'07.08'!$G$4:$G$11)+SUMIF('07.08'!$H$4:$H$11,A15,'07.08'!$I$4:$I$11)+SUMIF('07.08'!$J$4:$J$11,A15,'07.08'!$K$4:$K$11)+SUMIF('07.08'!$L$4:$L$11,A15,'07.08'!$M$4:$M$11)+SUMIF('07.08'!$N$4:$N$11,A15,'07.08'!$O$4:$O$11) -> 0 | O15: =SUMIF('08.08'!$B$4:$B$11,A15,'08.08'!$C$4:$C$11)+SUMIF('08.08'!$D$4:$D$11,A15,'08.08'!$E$4:$E$11)+SUMIF('08.08'!$F$4:$F$11,A15,'08.08'!$G$4:$G$11)+SUMIF('08.08'!$H$4:$H$11,A15,'08.08'!$I$4:$I$11)+SUMIF('08.08'!$J$4:$J$11,A15,'08.08'!$K$4:$K$11)+SUMIF('08.08'!$L$4:$L$11,A15,'08.08'!$M$4:$M$11)+SUMIF('08.08'!$N$4:$N$11,A15,'08.08'!$O$4:$O$11) -> 0 | P15: =SUMIF('09.08'!$B$4:$B$11,A15,'09.08'!$C$4:$C$11)+SUMIF('09.08'!$D$4:$D$11,A15,'09.08'!$E$4:$E$11)+SUMIF('09.08'!$F$4:$F$11,A15,'09.08'!$G$4:$G$11)+SUMIF('09.08'!$H$4:$H$11,A15,'09.08'!$I$4:$I$11)+SUMIF('09.08'!$J$4:$J$11,A15,'09.08'!$K$4:$K$11)+SUMIF('09.08'!$L$4:$L$11,A15,'09.08'!$M$4:$M$11)+SUMIF('09.08'!$N$4:$N$11,A15,'09.08'!$O$4:$O$11) -> 0 | Q15: =SUMIF('10.08'!$B$4:$B$11,A15,'10.08'!$C$4:$C$11)+SUMIF('10.08'!$D$4:$D$11,A15,'10.08'!$E$4:$E$11)+SUMIF('10.08'!$F$4:$F$11,A15,'10.08'!$G$4:$G$11)+SUMIF('10.08'!$H$4:$H$11,A15,'10.08'!$I$4:$I$11)+SUMIF('10.08'!$J$4:$J$11,A15,'10.08'!$K$4:$K$11)+SUMIF('10.08'!$L$4:$L$11,A15,'10.08'!$M$4:$M$11)+SUMIF('10.08'!$N$4:$N$11,A15,'10.08'!$O$4:$O$11) -> 0 | R15: =SUMIF('11.08'!$B$4:$B$11,A15,'11.08'!$C$4:$C$11)+SUMIF('11.08'!$D$4:$D$11,A15,'11.08'!$E$4:$E$11)+SUMIF('11.08'!$F$4:$F$11,A15,'11.08'!$G$4:$G$11)+SUMIF('11.08'!$H$4:$H$11,A15,'11.08'!$I$4:$I$11)+SUMIF('11.08'!$J$4:$J$11,A15,'11.08'!$K$4:$K$11)+SUMIF('11.08'!$L$4:$L$11,A15,'11.08'!$M$4:$M$11)+SUMIF('11.08'!$N$4:$N$11,A15,'11.08'!$O$4:$O$11) -> #N/A
A16: ='список продуктов'!A19 -> Колбаса | B16: ='список продуктов'!B19 -> палка | C16: ='список продуктов'!C19 | D16: ='список продуктов'!D19 | E16: ='список продуктов'!E19 -> Краткосрочный | F16: =SUM(I16:R16) -> #N/A | G16: =IFERROR(CEILING(F16/C16,1),"Введите занчения") -> Введите занчения | H16: =IFERROR(G16*D16,"Введите занчения") -> Введите занчения | I16: =SUMIF('02.08'!$B$4:$B$11,A16,'02.08'!$C$4:$C$11)+SUMIF('02.08'!$D$4:$D$11,A16,'02.08'!$E$4:$E$11)+SUMIF('02.08'!$F$4:$F$11,A16,'02.08'!$G$4:$G$11)+SUMIF('02.08'!$H$4:$H$11,A16,'02.08'!$I$4:$I$11)+SUMIF('02.08'!$J$4:$J$11,A16,'02.08'!$K$4:$K$11)+SUMIF('02.08'!$L$4:$L$11,A16,'02.08'!$M$4:$M$11)+SUMIF('02.08'!$N$4:$N$11,A16,'02.08'!$O$4:$O$11) -> 0 | J16: =SUMIF('03.08'!$B$4:$B$11,A16,'03.08'!$C$4:$C$11)+SUMIF('03.08'!$D$4:$D$11,A16,'03.08'!$E$4:$E$11)+SUMIF('03.08'!$F$4:$F$11,A16,'03.08'!$G$4:$G$11)+SUMIF('03.08'!$H$4:$H$11,A16,'03.08'!$I$4:$I$11)+SUMIF('03.08'!$J$4:$J$11,A16,'03.08'!$K$4:$K$11)+SUMIF('03.08'!$L$4:$L$11,A16,'03.08'!$M$4:$M$11)+SUMIF('03.08'!$N$4:$N$11,A16,'03.08'!$O$4:$O$11) -> 0 | K16: =SUMIF('04.08'!$B$4:$B$11,A16,'04.08'!$C$4:$C$11)+SUMIF('04.08'!$D$4:$D$11,A16,'04.08'!$E$4:$E$11)+SUMIF('04.08'!$F$4:$F$11,A16,'04.08'!$G$4:$G$11)+SUMIF('04.08'!$H$4:$H$11,A16,'04.08'!$I$4:$I$11)+SUMIF('04.08'!$J$4:$J$11,A16,'04.08'!$K$4:$K$11)+SUMIF('04.08'!$L$4:$L$11,A16,'04.08'!$M$4:$M$11)+SUMIF('04.08'!$N$4:$N$11,A16,'04.08'!$O$4:$O$11) -> 0 | L16: =SUMIF('05.08'!$B$4:$B$11,A16,'05.08'!$C$4:$C$11)+SUMIF('05.08'!$D$4:$D$11,A16,'05.08'!$E$4:$E$11)+SUMIF('05.08'!$F$4:$F$11,A16,'05.08'!$G$4:$G$11)+SUMIF('05.08'!$H$4:$H$11,A16,'05.08'!$I$4:$I$11)+SUMIF('05.08'!$J$4:$J$11,A16,'05.08'!$K$4:$K$11)+SUMIF('05.08'!$L$4:$L$11,A16,'05.08'!$M$4:$M$11)+SUMIF('05.08'!$N$4:$N$11,A16,'05.08'!$O$4:$O$11) -> 0 | M16: =SUMIF('06.08'!$B$4:$B$11,A16,'06.08'!$C$4:$C$11)+SUMIF('06.08'!$D$4:$D$11,A16,'06.08'!$E$4:$E$11)+SUMIF('06.08'!$F$4:$F$11,A16,'06.08'!$G$4:$G$11)+SUMIF('06.08'!$H$4:$H$11,A16,'06.08'!$I$4:$I$11)+SUMIF('06.08'!$J$4:$J$11,A16,'06.08'!$K$4:$K$11)+SUMIF('06.08'!$L$4:$L$11,A16,'06.08'!$M$4:$M$11)+SUMIF('06.08'!$N$4:$N$11,A16,'06.08'!$O$4:$O$11) -> 0 | N16: =SUMIF('07.08'!$B$4:$B$11,A16,'07.08'!$C$4:$C$11)+SUMIF('07.08'!$D$4:$D$11,A16,'07.08'!$E$4:$E$11)+SUMIF('07.08'!$F$4:$F$11,A16,'07.08'!$G$4:$G$11)+SUMIF('07.08'!$H$4:$H$11,A16,'07.08'!$I$4:$I$11)+SUMIF('07.08'!$J$4:$J$11,A16,'07.08'!$K$4:$K$11)+SUMIF('07.08'!$L$4:$L$11,A16,'07.08'!$M$4:$M$11)+SUMIF('07.08'!$N$4:$N$11,A16,'07.08'!$O$4:$O$11) -> 0 | O16: =SUMIF('08.08'!$B$4:$B$11,A16,'08.08'!$C$4:$C$11)+SUMIF('08.08'!$D$4:$D$11,A16,'08.08'!$E$4:$E$11)+SUMIF('08.08'!$F$4:$F$11,A16,'08.08'!$G$4:$G$11)+SUMIF('08.08'!$H$4:$H$11,A16,'08.08'!$I$4:$I$11)+SUMIF('08.08'!$J$4:$J$11,A16,'08.08'!$K$4:$K$11)+SUMIF('08.08'!$L$4:$L$11,A16,'08.08'!$M$4:$M$11)+SUMIF('08.08'!$N$4:$N$11,A16,'08.08'!$O$4:$O$11) -> 0 | P16: =SUMIF('09.08'!$B$4:$B$11,A16,'09.08'!$C$4:$C$11)+SUMIF('09.08'!$D$4:$D$11,A16,'09.08'!$E$4:$E$11)+SUMIF('09.08'!$F$4:$F$11,A16,'09.08'!$G$4:$G$11)+SUMIF('09.08'!$H$4:$H$11,A16,'09.08'!$I$4:$I$11)+SUMIF('09.08'!$J$4:$J$11,A16,'09.08'!$K$4:$K$11)+SUMIF('09.08'!$L$4:$L$11,A16,'09.08'!$M$4:$M$11)+SUMIF('09.08'!$N$4:$N$11,A16,'09.08'!$O$4:$O$11) -> 0 | Q16: =SUMIF('10.08'!$B$4:$B$11,A16,'10.08'!$C$4:$C$11)+SUMIF('10.08'!$D$4:$D$11,A16,'10.08'!$E$4:$E$11)+SUMIF('10.08'!$F$4:$F$11,A16,'10.08'!$G$4:$G$11)+SUMIF('10.08'!$H$4:$H$11,A16,'10.08'!$I$4:$I$11)+SUMIF('10.08'!$J$4:$J$11,A16,'10.08'!$K$4:$K$11)+SUMIF('10.08'!$L$4:$L$11,A16,'10.08'!$M$4:$M$11)+SUMIF('10.08'!$N$4:$N$11,A16,'10.08'!$O$4:$O$11) -> 0 | R16: =SUMIF('11.08'!$B$4:$B$11,A16,'11.08'!$C$4:$C$11)+SUMIF('11.08'!$D$4:$D$11,A16,'11.08'!$E$4:$E$11)+SUMIF('11.08'!$F$4:$F$11,A16,'11.08'!$G$4:$G$11)+SUMIF('11.08'!$H$4:$H$11,A16,'11.08'!$I$4:$I$11)+SUMIF('11.08'!$J$4:$J$11,A16,'11.08'!$K$4:$K$11)+SUMIF('11.08'!$L$4:$L$11,A16,'11.08'!$M$4:$M$11)+SUMIF('11.08'!$N$4:$N$11,A16,'11.08'!$O$4:$O$11) -> #N/A
